Workbook

Sheet EF_data_media_output
A1: id | B1: caption | C1: media_type | D1: media_product_type | E1: media_url | F1: thumbnail_url | G1: permalink | H1: timestamp | I1: like_count | J1: comments_count | K1: caption_counts | L1: date | M1: month_posted | N1: hour | O1: hashtag_counts
A2: 17978315999926827 | B2: Persiapan masuk Universitas luar negeri sambil 100% yakin bakal masuk Universitas impian dengan program EF University Preparation Program🎓🌎✨ Kamu tau ga EF ada program University Preparation yang bakal bantu seluruh persiapan mu buat masuk ke universitas impian di luar negeri langsung di EF Campus negara tujuan lho! 🏛️🎓 Pst! Ada jaminan 100% kamu bakal diterima di universitas luar negeri. Tunggu apa lagi, Yuk! Daftarkan dirimu dan mulai persiapan mulai dari sekarang!🚀✨ Hubungi kami: 0811-1370-3626 #efindonesia #efstudyabroad #efhomestay #efmoment | C2: VIDEO | D2: REELS | E2: https://scontent-ord5-2.cdninstagram.com/o1/v/t2/f2/m86/AQMoSdx4s9hiGOjKnrX-n8ew42gWqynZzesC4FEahKLQ516lw4Ze9w3BgKOJB5t18Q6rGqVH9_Ysl04WusLabvfkTjzhWnV1HH9gmEE.mp4?_nc_cat=103&_nc_sid=5e9851&_nc_ht=scontent-ord5-2.cdninstagram.com&_nc_ohc=LHOn4p_NQTAQ7kNvwFxfGKh&efg=eyJ2ZW5jb2RlX3RhZyI6Inhwdl9wcm9ncmVzc2l2ZS5JTlNUQUdSQU0uQ0xJUFMuQzMuNzIwLmRhc2hfYmFzZWxpbmVfMV92MSIsInhwdl9hc3NldF9pZCI6MjAwNjY3NDYwMzQ0OTM5NSwidmlfdXNlY2FzZV9pZCI6MTAwOTksImR1cmF0aW9uX3MiOjE2LCJ3YXRjaF90aW1lX3MiOjYzODksInVybGdlbl9zb3VyY2UiOiJ3d3cifQ%3D%3D&ccb=17-1&vs=14876f868d46759b&_nc_vs=HBksFQIYUmlnX3hwdl9yZWVsc19wZXJtYW5lbnRfc3JfcHJvZC84MjQ2MEU1MDNCRTlDNjEzRUMzNkZDRkUzQTVDNTBBOF92aWRlb19kYXNoaW5pdC5tcDQVAALIARIAFQIYOnBhc3N0aHJvdWdoX2V2ZXJzdG9yZS9HTGpreVNGRGVOVktHdjBEQVBnMTZmbS1vdXRTYnN0VEFRQUYVAgLIARIAKAAYABsCiAd1c2Vfb2lsATEScHJvZ3Jlc3NpdmVfcmVjaXBlATEVAAAm5vDY7urDkAcVAigCQzMsF0AwMzMzMzMzGBJkYXNoX2Jhc2VsaW5lXzFfdjERAHX-B2XmnQEA&_nc_gid=abiAmay4kHKk2CacW0aRhA&edm=AL-3X8kEAAAA&_nc_zt=28&oh=00_AfcIkgbhtxwEuzsnb6QF_MI4Qc6CGsZCF6IADyciwMis4Q&oe=68FA822C | F2: https://scontent-ord5-2.cdninstagram.com/v/t51.71878-15/568021499_844581908226404_5780055324957422341_n.jpg?stp=dst-jpg_e35_tt6&_nc_cat=110&ccb=1-7&_nc_sid=18de74&efg=eyJlZmdfdGFnIjoiQ0xJUFMuYmVzdF9pbWFnZV91cmxnZW4uQzMifQ%3D%3D&_nc_ohc=1gmwEppzzC4Q7kNvwERBZ4S&_nc_oc=Adm93A9lkkp-OVBjMrq3Y48BaPpzIJnPzgZYhIfq1VJdvL4x89hYzheRMXIhmvPvlk8&_nc_zt=23&_nc_ht=scontent-ord5-2.cdninstagram.com&edm=AL-3X8kEAAAA&_nc_gid=abiAmay4kHKk2CacW0aRhA&oh=00_AfeoxsWofAeONtHV4uAgX0U8TjSWEc89kWbWrcvUJxGipg&oe=68FE47D7 | G2: https://www.instagram.com/reel/DQETcTekaPU/ | H2: 2025-10-21T10:15:03+0000 | I2: 28 | J2: 0 | K2: =LEN(B2) -> 562 | L2: =(DATEVALUE(LEFT(H2,10))+TIMEVALUE(MID(H2,12,8)))+(7/24) -> 45951.719 | M2: =TEXT(L2,"mmmm") -> October | N2: =VALUE(MID(H2,12,2)) -> 10 | O2: =LEN(B2)-LEN(SUBSTITUTE(B2,"#","")) -> 4
A3: 18084482953945506 | B3: Masih usia 7-18 tahun tapi udah ke luar negeri ga bareng orang tua ke destinasi seperti New York, Singapore, Sydney dan masi banyak lagi!❄️🌎✨ Yuk! Sekarang giliran mu untuk isi liburan akhir tahun mu (December 2025 - Januari 2026) dengan EF Winter Camp 2025❄️☃️ Benefit ikut EF Winter Camp 2025❄️ ✅ Kegiatan seru & edukatif yang dirancang untuk eksplorasi budaya di negara tujuan ✅ Berteman dengan pelajar internasional dan tingkatkan kemampuan komunikasi global ✅ Didampingi oleh tim EF profesional—belajar, bermain, dan eksplorasi dengan aman dan menyenangkan! Jangan lewatkan kesempatan untuk membuat liburan sekolahmu lebih bermakna! 📲 Daftar sekarang via WhatsApp: +62 811-1370-3626 #efindonesia #efstudyabroad #efhomestay #efmoment #efwintercamp2025 #studyabroad #exploretheworld #efoxford #efnewyorkcity #efsydney #wintercamp #efcambridge | C3: VIDEO | D3: REELS | E3: https://scontent-ord5-2.cdninstagram.com/o1/v/t2/f2/m86/AQMxBAj0UPw0rkAbmy3sLelXCRW7HgFXLpTuxqrmz672yPx_Yv0C8fn6BBV7bZdRVUj_xrgrJsbJliEb0SF3wwTgXWbuSFYuhbOw2Nw.mp4?_nc_cat=105&_nc_sid=5e9851&_nc_ht=scontent-ord5-2.cdninstagram.com&_nc_ohc=y6NjuIoOoPIQ7kNvwFFKxSY&efg=eyJ2ZW5jb2RlX3RhZyI6Inhwdl9wcm9ncmVzc2l2ZS5JTlNUQUdSQU0uQ0xJUFMuQzMuNzIwLmRhc2hfYmFzZWxpbmVfMV92MSIsInhwdl9hc3NldF9pZCI6MTE2NDk0NTA4NTAyMzczNiwidmlfdXNlY2FzZV9pZCI6MTAwOTksImR1cmF0aW9uX3MiOjksIndhdGNoX3RpbWVfcyI6MTg1NjcsInVybGdlbl9zb3VyY2UiOiJ3d3cifQ%3D%3D&ccb=17-1&vs=23e657b1ab264be2&_nc_vs=HBksFQIYUmlnX3hwdl9yZWVsc19wZXJtYW5lbnRfc3JfcHJvZC84MDRCRDg2REZFM0YxOTEyNzgyODJDNzBFRDREQTk4RF92aWRlb19kYXNoaW5pdC5tcDQVAALIARIAFQIYOnBhc3N0aHJvdWdoX2V2ZXJzdG9yZS9HS0VDMmlGYjdNMFBqdzBEQUp4VTNqSDNUdjFfYnN0VEFRQUYVAgLIARIAKAAYABsCiAd1c2Vfb2lsATEScHJvZ3Jlc3NpdmVfcmVjaXBlATEVAAAm8JfOn93gkQQVAigCQzMsF0Aju2RaHKwIGBJkYXNoX2Jhc2VsaW5lXzFfdjERAHX-B2XmnQEA&_nc_gid=abiAmay4kHKk2CacW0aRhA&edm=AL-3X8kEAAAA&_nc_zt=28&oh=00_Afe_T_4agrU1GYEMQKC2-0C3XjG6xhB7pICkUxHicSnu2w&oe=68FA6C12 | F3: https://scontent-ord5-2.cdninstagram.com/v/t51.82787-15/566799258_18487523197079669_3645751247302178371_n.jpg?stp=dst-jpg_e35_tt6&_nc_cat=110&ccb=1-7&_nc_sid=18de74&efg=eyJlZmdfdGFnIjoiQ0xJUFMuYmVzdF9pbWFnZV91cmxnZW4uQzMifQ%3D%3D&_nc_ohc=VfIon_xNGegQ7kNvwGUahw7&_nc_oc=AdmQ_1LDydXujZnWWslQgS3UP37x72sypsEax_ZPsNfpf3C4XkaYCf1i5MXldGg0N-s&_nc_zt=23&_nc_ht=scontent-ord5-2.cdninstagram.com&edm=AL-3X8kEAAAA&_nc_gid=abiAmay4kHKk2CacW0aRhA&oh=00_Afe4V924uRMvlxM4o1xECKRlayJy8l5vLwCgtuU1ebR7wg&oe=68FE5D15 | G3: https://www.instagram.com/reel/DQBvLT-kUG2/ | H3: 2025-10-20T10:15:03+0000 | I3: 179 | J3: 1 | K3: =LEN(B3) -> 852 | L3: =(DATEVALUE(LEFT(H3,10))+TIMEVALUE(MID(H3,12,8)))+(7/24) -> 45950.719 | M3: =TEXT(L3,"mmmm") -> October | N3: =VALUE(MID(H3,12,2)) -> 10 | O3: =LEN(B3)-LEN(SUBSTITUTE(B3,"#","")) -> 12
A4: 17958236612989795 | B4: EF bukan cuman belajar bahasa di negara tujuan, tapi juga tambah koneksi international dan belajar budaya dari teman-teman berbagai negara!🤩✨ Ingin wujudkan mimpi Study Abroad mu bareng EF? Jadikan liburan sekolah mu lebih seru, bermanfaat, dan tak terlupakan bersama EF! 📚 📱 WA: 0811-1370-3626 #efindonesia #efstudyabroad #efhomestay #efnewyork #efmoment #EF #studyabroad #memories | C4: VIDEO | D4: REELS | E4: https://scontent-ord5-1.cdninstagram.com/o1/v/t2/f2/m86/AQOkF0KJM1Ze6yoyKYzrKboIQ5UGiVZADodpJ8bvHpqJq42_UzukushgkTudK-fMRumXwCWxj8bTsj2KcfS6y71WPg_014dJ4hCfI54.mp4?_nc_cat=111&_nc_sid=5e9851&_nc_ht=scontent-ord5-1.cdninstagram.com&_nc_ohc=KJ5Zk-7mC4UQ7kNvwFlculq&efg=eyJ2ZW5jb2RlX3RhZyI6Inhwdl9wcm9ncmVzc2l2ZS5JTlNUQUdSQU0uQ0xJUFMuQzMuNzIwLmRhc2hfYmFzZWxpbmVfMV92MSIsInhwdl9hc3NldF9pZCI6ODY3MjU0MzQ1NjMzNDY5LCJ2aV91c2VjYXNlX2lkIjoxMDA5OSwiZHVyYXRpb25fcyI6NjUsIndhdGNoX3RpbWVfcyI6MTU4NjksInVybGdlbl9zb3VyY2UiOiJ3d3cifQ%3D%3D&ccb=17-1&vs=38a6f2c64e7c60e4&_nc_vs=HBksFQIYUmlnX3hwdl9yZWVsc19wZXJtYW5lbnRfc3JfcHJvZC8yQTQ5MEM5NzBENEVFQjBEMTUwNUNEMTFEMzJFMzJBNF92aWRlb19kYXNoaW5pdC5tcDQVAALIARIAFQIYOnBhc3N0aHJvdWdoX2V2ZXJzdG9yZS9HQ2k2d3lFTTFSWFBZUThFQUdvYU9kaFJ2bE44YnN0VEFRQUYVAgLIARIAKAAYABsCiAd1c2Vfb2lsATEScHJvZ3Jlc3NpdmVfcmVjaXBlATEVAAAm-rqcs-ywigMVAigCQzMsF0BQRDlYEGJOGBJkYXNoX2Jhc2VsaW5lXzFfdjERAHX-B2XmnQEA&_nc_gid=abiAmay4kHKk2CacW0aRhA&edm=AL-3X8kEAAAA&_nc_zt=28&oh=00_AffcZ5YkuoMTkkPi505l2N9ghZWFrKaSgPWpFiZW8tBUmA&oe=68FA5BF0 | F4: https://scontent-ord5-3.cdninstagram.com/v/t51.71878-15/564989870_1787270108618498_7631135594495211703_n.jpg?stp=dst-jpg_e35_tt6&_nc_cat=109&ccb=1-7&_nc_sid=18de74&efg=eyJlZmdfdGFnIjoiQ0xJUFMuYmVzdF9pbWFnZV91cmxnZW4uQzMifQ%3D%3D&_nc_ohc=ne8_KBOkTakQ7kNvwE7diqj&_nc_oc=AdmlH9v_GPpK2GVdh7I91dp1n2pc6KRr0IbUU89ELafVkpQHKCLrReALbsPPv2DizOs&_nc_zt=23&_nc_ht=scontent-ord5-3.cdninstagram.com&edm=AL-3X8kEAAAA&_nc_gid=abiAmay4kHKk2CacW0aRhA&oh=00_Afdcjz0Y0FNWB33b6O859m9oorPmTQfoAHxmW0h6WTZQDg&oe=68FE6808 | G4: https://www.instagram.com/reel/DP3cHkcEWh-/ | H4: 2025-10-16T10:10:11+0000 | I4: 33 | J4: 0 | K4: =LEN(B4) -> 388 | L4: =(DATEVALUE(LEFT(H4,10))+TIMEVALUE(MID(H4,12,8)))+(7/24) -> 45946.715 | M4: =TEXT(L4,"mmmm") -> October | N4: =VALUE(MID(H4,12,2)) -> 10 | O4: =LEN(B4)-LEN(SUBSTITUTE(B4,"#","")) -> 8
A5: 18375432955150136 | B5: POV: Belajar bahasa bareng temen dari berbagai negara di EF Campus luar negeri!🤩🌎✨ EF bukan cuma belajar Bahasa Inggris, kamu juga belajar bahasa lainnya seperti Jepang, Jerman, Spanyol dan lain-lain di negaranya langsung!🤩✨ Ingin wujudkan mimpi Study Abroad mu bareng EF? Jadikan liburan sekolah mu lebih seru, bermanfaat, dan tak terlupakan bersama EF! 📚 📱 WA: 0811-1370-3626 #efindonesia #efstudyabroad #efhomestay #efoxford #efmoment #EF #efjapan #efwintercamp2025 #studyabroad #memories | C5: VIDEO | D5: REELS | E5: https://scontent-ord5-2.cdninstagram.com/o1/v/t2/f2/m86/AQORITv2tsouHMKsVsYcHFmia02cQnxg0O15T45sVv3WdN64o6zofKoVJVuuFCKAEhvsWSOq4L4NZVj2QwdSVOS8yb8t1fHoYnGikSg.mp4?_nc_cat=105&_nc_sid=5e9851&_nc_ht=scontent-ord5-2.cdninstagram.com&_nc_ohc=QNqMbmTj_AAQ7kNvwEk6s7M&efg=eyJ2ZW5jb2RlX3RhZyI6Inhwdl9wcm9ncmVzc2l2ZS5JTlNUQUdSQU0uQ0xJUFMuQzMuNzIwLmRhc2hfYmFzZWxpbmVfMV92MSIsInhwdl9hc3NldF9pZCI6NzcwMTM3ODIyNjg1NTkyLCJ2aV91c2VjYXNlX2lkIjoxMDA5OSwiZHVyYXRpb25fcyI6MTQsIndhdGNoX3RpbWVfcyI6ODI1MiwidXJsZ2VuX3NvdXJjZSI6Ind3dyJ9&ccb=17-1&vs=c732d047d24f867d&_nc_vs=HBksFQIYUmlnX3hwdl9yZWVsc19wZXJtYW5lbnRfc3JfcHJvZC9DMTQ1NjQzMTE3MkJBNTBEQkY5RkVFOTY5NDI5MkNBRV92aWRlb19kYXNoaW5pdC5tcDQVAALIARIAFQIYOnBhc3N0aHJvdWdoX2V2ZXJzdG9yZS9HUGdNdkNGV2hWR0ZpUElDQUpZTHhzQUR4elpkYnN0VEFRQUYVAgLIARIAKAAYABsCiAd1c2Vfb2lsATEScHJvZ3Jlc3NpdmVfcmVjaXBlATEVAAAmsKbL9fWb3gIVAigCQzMsF0Asu2RaHKwIGBJkYXNoX2Jhc2VsaW5lXzFfdjERAHX-B2XmnQEA&_nc_gid=abiAmay4kHKk2CacW0aRhA&edm=AL-3X8kEAAAA&_nc_zt=28&oh=00_Afeusx4JTlhcopEsVtLvQMaPgTivPCuyTDuvEBGN-Cq2mQ&oe=68FA6796 | F5: https://scontent-ord5-2.cdninstagram.com/v/t51.82787-15/563563659_18486261172079669_6477129562393288348_n.jpg?stp=dst-jpg_e35_tt6&_nc_cat=102&ccb=1-7&_nc_sid=18de74&efg=eyJlZmdfdGFnIjoiQ0xJUFMuYmVzdF9pbWFnZV91cmxnZW4uQzMifQ%3D%3D&_nc_ohc=kAtu-e-HDEYQ7kNvwEROUk7&_nc_oc=AdlyjuDertbK-l3HSh_hm2Rj9T5Rn5-uaLuV10SDAm_U6r-51Ej_W0_E3yh-ikUO2ks&_nc_zt=23&_nc_ht=scontent-ord5-2.cdninstagram.com&edm=AL-3X8kEAAAA&_nc_gid=abiAmay4kHKk2CacW0aRhA&oh=00_AfcZmirlKvq2UTUwwhJfcvrl1mYGQfDePlPIrNq59JxJmw&oe=68FE5B06 | G5: https://www.instagram.com/reel/DP00aUXkfY6/ | H5: 2025-10-15T10:00:05+0000 | I5: 43 | J5: 0 | K5: =LEN(B5) -> 500 | L5: =(DATEVALUE(LEFT(H5,10))+TIMEVALUE(MID(H5,12,8)))+(7/24) -> 45945.708 | M5: =TEXT(L5,"mmmm") -> October | N5: =VALUE(MID(H5,12,2)) -> 10 | O5: =LEN(B5)-LEN(SUBSTITUTE(B5,"#","")) -> 10
A6: 18092752663771972 | B6: Rencanakan liburan akhir tahun mu bareng EF di destinasi-destinasi menarik seperti New York, London, Gold Coast Australia, Isle of Wight dan masih banyak lagi!❄️🤩 Pendaftaraan untuk Winter 2025 masih dibuka! Yuk segara daftar ❄️☃️🧣✈️ Benefit ikut EF Winter Camp 2025❄️ ✅ Kegiatan seru & edukatif yang dirancang untuk eksplorasi budaya di negara tujuan ✅ Berteman dengan pelajar internasional dan tingkatkan kemampuan komunikasi global ✅ Didampingi oleh tim EF profesional—belajar, bermain, dan eksplorasi dengan aman dan menyenangkan! Jangan lewatkan kesempatan untuk membuat liburan sekolahmu lebih bermakna! 📲 Daftar sekarang via WhatsApp: +62 811-1370-3626 #efindonesia #efstudyabroad #efhomestay #efmoment #efwintercamp2025 #studyabroad #exploretheworld #efoxford #efnewyorkcity #efsydney #wintercamp #efcambridge | C6: VIDEO | D6: REELS | E6: https://scontent-ord5-2.cdninstagram.com/o1/v/t2/f2/m86/AQPBq7hL9niNRGO9122yrPfISL_HsOuRfOUXoelmntkwA6bYOEmmpYJEoY-ZnoABKHQnw8K58NGOvC95wsEoq-RE2WcRq7wZvWe4rVs.mp4?_nc_cat=103&_nc_sid=5e9851&_nc_ht=scontent-ord5-2.cdninstagram.com&_nc_ohc=ia1xVoaQbGEQ7kNvwFt1mNl&efg=eyJ2ZW5jb2RlX3RhZyI6Inhwdl9wcm9ncmVzc2l2ZS5JTlNUQUdSQU0uQ0xJUFMuQzMuNzIwLmRhc2hfYmFzZWxpbmVfMV92MSIsInhwdl9hc3NldF9pZCI6MTI2MzE5MDM4ODkwODkxOSwidmlfdXNlY2FzZV9pZCI6MTAwOTksImR1cmF0aW9uX3MiOjI2LCJ3YXRjaF90aW1lX3MiOjIxMTUzLCJ1cmxnZW5fc291cmNlIjoid3d3In0%3D&ccb=17-1&vs=3f178bdc835a01f8&_nc_vs=HBksFQIYUmlnX3hwdl9yZWVsc19wZXJtYW5lbnRfc3JfcHJvZC8zMDQ4NDRGRTY2MzY3QUE3RkNGNzJDQTNFN0Q2N0Q5Rl92aWRlb19kYXNoaW5pdC5tcDQVAALIARIAFQIYOnBhc3N0aHJvdWdoX2V2ZXJzdG9yZS9HUFh6a2lIZmR5X05jN0VEQUdEdF9RbmRiYTlGYnN0VEFRQUYVAgLIARIAKAAYABsCiAd1c2Vfb2lsATEScHJvZ3Jlc3NpdmVfcmVjaXBlATEVAAAm7o3R5q23vgQVAigCQzMsF0A61T987ZFoGBJkYXNoX2Jhc2VsaW5lXzFfdjERAHX-B2XmnQEA&_nc_gid=abiAmay4kHKk2CacW0aRhA&edm=AL-3X8kEAAAA&_nc_zt=28&oh=00_AfdYAqYz354Tm1-Od9fJg7Yth1_EP-hRYkBTDY3KV7RMFA&oe=68FA6848 | F6: https://scontent-ord5-3.cdninstagram.com/v/t51.82787-15/562532398_18485794258079669_9134842225559758134_n.jpg?stp=dst-jpg_e35_tt6&_nc_cat=107&ccb=1-7&_nc_sid=18de74&efg=eyJlZmdfdGFnIjoiQ0xJUFMuYmVzdF9pbWFnZV91cmxnZW4uQzMifQ%3D%3D&_nc_ohc=HLz3SEFnH6wQ7kNvwF_H14R&_nc_oc=Adn2YRD5d_lmo_AsksKtc1saC2szO1A_7rMzdfxbd885_5GSn_8EETIxs-YIZvNejEE&_nc_zt=23&_nc_ht=scontent-ord5-3.cdninstagram.com&edm=AL-3X8kEAAAA&_nc_gid=abiAmay4kHKk2CacW0aRhA&oh=00_Afd9Ti4guoFrb5T1W7KFd9EcqZM0ejjpAGfS1Ojg7VyCWw&oe=68FE70B9 | G6: https://www.instagram.com/reel/DPvqWHQEdMT/ | H6: 2025-10-13T10:00:08+0000 | I6: 167 | J6: 0 | K6: =LEN(B6) -> 825 | L6: =(DATEVALUE(LEFT(H6,10))+TIMEVALUE(MID(H6,12,8)))+(7/24) -> 45943.708 | M6: =TEXT(L6,"mmmm") -> October | N6: =VALUE(MID(H6,12,2)) -> 10 | O6: =LEN(B6)-LEN(SUBSTITUTE(B6,"#","")) -> 12
A7: 18107034529593766 | B7: Kalo zodiak kamu jadi kota, kamu bakal cocok tinggal di mana nih?👀🌎✨ Gemini di Tokyo? Pisces di Santorini? Atau Leo yang selalu bersinar di Barcelona?☀️ Bersama EF, kamu bisa ngerasain vibes setiap kota ini sambil belajar bahasa di salah satu dari 50+ EF School di seluruh dunia!🚀 Yuk, mulai perjalanan Study Abroad kamu dan rasain serunya belajar sambil jelajahi dunia!📚✨ 📩 Konsultasi sekarang via DM atau WA: 0811-1370-3626 #efindonesia #efstudyabroad #efmoment #studyabroad #travel #EF #learnlanguagesabroad #yourcitymatch | C7: CAROUSEL_ALBUM | D7: FEED | E7: https://scontent-ord5-2.cdninstagram.com/v/t51.82787-15/561288839_18484955530079669_1918396462737381820_n.jpg?stp=dst-jpg_e35_tt6&_nc_cat=102&ccb=1-7&_nc_sid=18de74&efg=eyJlZmdfdGFnIjoiQ0FST1VTRUxfSVRFTS5iZXN0X2ltYWdlX3VybGdlbi5DMyJ9&_nc_ohc=eSYjEawqT5EQ7kNvwFG9V-A&_nc_oc=AdlaY5NLLQzI96oM9kO8Z8DUT1synXfESYnPwvltS3H1z9keKWFZWqfQ0X7xyckpJKc&_nc_zt=23&_nc_ht=scontent-ord5-2.cdninstagram.com&edm=AL-3X8kEAAAA&_nc_gid=abiAmay4kHKk2CacW0aRhA&oh=00_AfclsH4nSdLj5984sAsj-PvqP2M_OM78ZMouwxdVIrWFUA&oe=68FE6BDB | G7: https://www.instagram.com/p/DPlaouoETv0/ | H7: 2025-10-09T10:10:16+0000 | I7: 110 | J7: 2 | K7: =LEN(B7) -> 535 | L7: =(DATEVALUE(LEFT(H7,10))+TIMEVALUE(MID(H7,12,8)))+(7/24) -> 45939.715 | M7: =TEXT(L7,"mmmm") -> October | N7: =VALUE(MID(H7,12,2)) -> 10 | O7: =LEN(B7)-LEN(SUBSTITUTE(B7,"#","")) -> 8
A8: 18042788789676236 | B8: Hi EFriends! Kenalan yuk sama Kak Heni (39 tahun), yang memilih untuk keluar dari zona nyaman dan mengembangkan potensi diri lewat program EF Study Abroad selama 4 minggu di EF Manchester! 🇬🇧🤩 Selama di Manchester bareng EF. Kak Heni punya satu kata untuk menggambarkan seluruh pengalamannya: FANTASTIC! Dari belajar bahasa Inggris di lingkungan internasional, ketemu teman baru dari berbagai negara, sampai ngerasain langsung kehidupan di Inggris — semuanya jadi pengalaman tak terlupakan! 🛩️🤩✨ Kamu juga bisa, lho, kembangin potensi diri dan belajar langsung di negara impianmu bareng EF! 🌏 Yuk, mulai petualangan kamu sekarang! 📲 Hubungi kami di WhatsApp: 0811-1370-3626 #efindonesia #efstudyabroad #efmoment #efmanchester #efexperience #studyabroadjourney #belajardiinggris #efhomestay | C8: CAROUSEL_ALBUM | D8: FEED | E8: https://scontent-ord5-3.cdninstagram.com/v/t51.82787-15/561372676_18484581478079669_6404731693164481067_n.jpg?stp=dst-jpg_e35_tt6&_nc_cat=107&ccb=1-7&_nc_sid=18de74&efg=eyJlZmdfdGFnIjoiQ0FST1VTRUxfSVRFTS5iZXN0X2ltYWdlX3VybGdlbi5DMyJ9&_nc_ohc=K2VqPgBrMMAQ7kNvwEWJAuf&_nc_oc=AdlSzywzvR1BcywW3FfTlDK0Nn9bfN_ZtqQMfUGhp7AY0wY7lBRLHTpRvErEkNxD4Es&_nc_zt=23&_nc_ht=scontent-ord5-3.cdninstagram.com&edm=AL-3X8kEAAAA&_nc_gid=abiAmay4kHKk2CacW0aRhA&oh=00_AfdgXlZMgCC8XjIkm9uHtqKOOkRZLEF8WCco4PUDYrqjaQ&oe=68FE5DB3 | G8: https://www.instagram.com/p/DPgQ4HKETWP/ | H8: 2025-10-07T10:08:46+0000 | I8: 34 | J8: 0 | K8: =LEN(B8) -> 801 | L8: =(DATEVALUE(LEFT(H8,10))+TIMEVALUE(MID(H8,12,8)))+(7/24) -> 45937.714 | M8: =TEXT(L8,"mmmm") -> October | N8: =VALUE(MID(H8,12,2)) -> 10 | O8: =LEN(B8)-LEN(SUBSTITUTE(B8,"#","")) -> 8
A9: 18070889402223745 | B9: Rencanakan liburan akhir tahun mu bareng EF di destinasi-destinasi menarik seperti New York, London, Gold Coast Australia, Isle of Wight dan masih banyak lagi!❄️🤩 Pendaftaraan untuk Winter 2025 masih dibuka! Yuk segara daftar ❄️☃️🧣✈️ Benefit ikut EF Winter Camp 2025❄️ ✅ Kegiatan seru & edukatif yang dirancang untuk eksplorasi budaya di negara tujuan ✅ Berteman dengan pelajar internasional dan tingkatkan kemampuan komunikasi global ✅ Didampingi oleh tim EF profesional—belajar, bermain, dan eksplorasi dengan aman dan menyenangkan! Jangan lewatkan kesempatan untuk membuat liburan sekolahmu lebih bermakna! 📲 Daftar sekarang via WhatsApp: +62 811-1370-3626 #efindonesia #efstudyabroad #efhomestay #efmoment #efwintercamp2025 #studyabroad #exploretheworld #efoxford #efnewyorkcity #efsydney #wintercamp #efcambridge | C9: VIDEO | D9: REELS | E9: https://scontent-ord5-2.cdninstagram.com/o1/v/t2/f2/m86/AQM5jmNuRwS4TwYfoIl9zMpIc7wFyMhO7O6WMPhyRUGgjebXXXMh_toupUQfY2PhozXum_c1Na2gS_8m0edzz7Fnk8nWtXgM6ySmrpg.mp4?_nc_cat=110&_nc_sid=5e9851&_nc_ht=scontent-ord5-2.cdninstagram.com&_nc_ohc=GOKn50FsoC8Q7kNvwGjG8B-&efg=eyJ2ZW5jb2RlX3RhZyI6Inhwdl9wcm9ncmVzc2l2ZS5JTlNUQUdSQU0uQ0xJUFMuQzMuNzIwLmRhc2hfYmFzZWxpbmVfMV92MSIsInhwdl9hc3NldF9pZCI6MTEyMzk1OTE4MzAzOTI4MywidmlfdXNlY2FzZV9pZCI6MTAwOTksImR1cmF0aW9uX3MiOjMwLCJ3YXRjaF90aW1lX3MiOjEwNjEzLCJ1cmxnZW5fc291cmNlIjoid3d3In0%3D&ccb=17-1&vs=9402c59d51a72dbb&_nc_vs=HBksFQIYUmlnX3hwdl9yZWVsc19wZXJtYW5lbnRfc3JfcHJvZC8xNDRGNDdCNkYzNjdBRjFFRUEzQkU2MDgzMkU3QUVBQ192aWRlb19kYXNoaW5pdC5tcDQVAALIARIAFQIYOnBhc3N0aHJvdWdoX2V2ZXJzdG9yZS9HQ1Y1Y1NIaGZHTFI1QlVFQU96QjdueW5PSEZvYnFfRUFBQUYVAgLIARIAKAAYABsCiAd1c2Vfb2lsATEScHJvZ3Jlc3NpdmVfcmVjaXBlATEVAAAm5uzGvYSP_wMVAigCQzMsF0A-XbItDlYEGBJkYXNoX2Jhc2VsaW5lXzFfdjERAHX-B2XmnQEA&_nc_gid=abiAmay4kHKk2CacW0aRhA&edm=AL-3X8kEAAAA&_nc_zt=28&oh=00_AffYMcjlVKnpbb_k_fpBgHEXpsCa5uZ6GEJA0e0vNxCfrQ&oe=68FA57DB | F9: https://scontent-ord5-3.cdninstagram.com/v/t51.82787-15/558901604_18484544242079669_4427550672337751309_n.jpg?stp=dst-jpg_e35_tt6&_nc_cat=100&ccb=1-7&_nc_sid=18de74&efg=eyJlZmdfdGFnIjoiQ0xJUFMuYmVzdF9pbWFnZV91cmxnZW4uQzMifQ%3D%3D&_nc_ohc=S6MLYrO2DZkQ7kNvwGjtr1Y&_nc_oc=AdkNtNmqTxCVs2An3QtKC2fak3Twoklm4z83t7vXCo4D2ZOCvD4fRHuk1Wgthsw_p0E&_nc_zt=23&_nc_ht=scontent-ord5-3.cdninstagram.com&edm=AL-3X8kEAAAA&_nc_gid=abiAmay4kHKk2CacW0aRhA&oh=00_Afc7gW7rj8lhYQFeMbvCearFO6DRVTIh46PyrMIHXXpq-Q&oe=68FE6775 | G9: https://www.instagram.com/reel/DPdqxukEc0W/ | H9: 2025-10-06T10:14:40+0000 | I9: 29 | J9: 0 | K9: =LEN(B9) -> 825 | L9: =(DATEVALUE(LEFT(H9,10))+TIMEVALUE(MID(H9,12,8)))+(7/24) -> 45936.719 | M9: =TEXT(L9,"mmmm") -> October | N9: =VALUE(MID(H9,12,2)) -> 10 | O9: =LEN(B9)-LEN(SUBSTITUTE(B9,"#","")) -> 12
A10: 18506222614066133 | B10: Belajar bahasa di luar negeri bareng EF lebih seru di 50+ destinasi EF School yang tersebar di berbagai negara dan 10 pilihan bahasa!🤩🌎✨ ✅ Belajar bahasa asing langsung di destinasi impianmu ✅ Mendapat bimbingan Visa, tiket penerbangan dan akomodasi ✅ Keberangkatan fleksibel dengan durasi minimal 2 minggu - 6 bulan ✅ Banyak pilihan destinasi, waktu keberangkatan dan level bahasa Konsultasi sekarang untuk menemukan program dan destinasi terbaik sesuai dengan minat Anda! WA: +62 811 1370 3626 #efindonesia #efstudyabroad #efhomestay #efmoment #5120x1080 | C10: VIDEO | D10: REELS | E10: https://scontent-ord5-3.cdninstagram.com/o1/v/t2/f2/m86/AQMloxix2Sk8hUswoNw-uK3pAiTmER2Gvs1vHuVkTWq6K7MIgQhrXzK-kVChIleWNNIJI6Km3BnH3H4ZA38ZaFkAA_9_7pDAu2epkQ0.mp4?_nc_cat=107&_nc_sid=5e9851&_nc_ht=scontent-ord5-3.cdninstagram.com&_nc_ohc=OjU0RqE9MzYQ7kNvwF8OA94&efg=eyJ2ZW5jb2RlX3RhZyI6Inhwdl9wcm9ncmVzc2l2ZS5JTlNUQUdSQU0uQ0xJUFMuQzMuMTI4MC5kYXNoX2Jhc2VsaW5lXzFfdjEiLCJ4cHZfYXNzZXRfaWQiOjc4NTk0MjEyMTAyODE5NywidmlfdXNlY2FzZV9pZCI6MTAwOTksImR1cmF0aW9uX3MiOjMzLCJ3YXRjaF90aW1lX3MiOjM0MzEwLCJ1cmxnZW5fc291cmNlIjoid3d3In0%3D&ccb=17-1&vs=e04361789986e1b6&_nc_vs=HBksFQIYUmlnX3hwdl9yZWVsc19wZXJtYW5lbnRfc3JfcHJvZC80OTQ4NEI5NTRDQUNCRTZFM0E2RjU4N0Y3Q0I3MkFBM192aWRlb19kYXNoaW5pdC5tcDQVAALIARIAFQIYOnBhc3N0aHJvdWdoX2V2ZXJzdG9yZS9HTG85UUNGdjRjQlFsRjRGQUtScndIZlBsOGRhYnFfRUFBQUYVAgLIARIAKAAYABsCiAd1c2Vfb2lsATEScHJvZ3Jlc3NpdmVfcmVjaXBlATEVAAAmyumAj-2z5QIVAigCQzMsF0BAgAAAAAAAGBJkYXNoX2Jhc2VsaW5lXzFfdjERAHX-B2XmnQEA&_nc_gid=abiAmay4kHKk2CacW0aRhA&edm=AL-3X8kEAAAA&_nc_zt=28&oh=00_AffxZoz1Uv2ujUJ1EsRQdrzuedaPtE-Ib53aFnQxcT4mTw&oe=68FA7160 | F10: https://scontent-ord5-2.cdninstagram.com/v/t51.82787-15/557239138_18483470230079669_3076725115660526296_n.jpg?stp=dst-jpg_e35_tt6&_nc_cat=105&ccb=1-7&_nc_sid=18de74&efg=eyJlZmdfdGFnIjoiQ0xJUFMuYmVzdF9pbWFnZV91cmxnZW4uQzMifQ%3D%3D&_nc_ohc=RCrM6PuCZlMQ7kNvwErcV3b&_nc_oc=Adksc78l_jhTpY33c16lSeOH40w0ITi3FrD6SMiJjqWgWPAiX1DwjSqDu58kvb8Egus&_nc_zt=23&_nc_ht=scontent-ord5-2.cdninstagram.com&edm=AL-3X8kEAAAA&_nc_gid=abiAmay4kHKk2CacW0aRhA&oh=00_Afe5hQQXlARSBiZ64lmOieUuycre3QJTwOf37PHElF6guQ&oe=68FE4FCA | G10: https://www.instagram.com/reel/DPQzJ5MEb3U/ | H10: 2025-10-01T10:01:43+0000 | I10: 182 | J10: 0 | K10: =LEN(B10) -> 566 | L10: =(DATEVALUE(LEFT(H10,10))+TIMEVALUE(MID(H10,12,8)))+(7/24) -> 45931.71 | M10: =TEXT(L10,"mmmm") -> October | N10: =VALUE(MID(H10,12,2)) -> 10 | O10: =LEN(B10)-LEN(SUBSTITUTE(B10,"#","")) -> 5
A11: 18095645830708018 | B11: Rencanakan liburan akhir tahun mu bareng EF di destinasi-destinasi menarik seperti New York, London, Gold Coast Australia, Isle of Wight dan masih banyak lagi!❄️🤩 Pendaftaraan untuk Winter 2025 sudah dibuka! Yuk segara daftar ❄️☃️🧣✈️ Benefit ikut EF Winter Camp 2025❄️ ✅ Kegiatan seru & edukatif yang dirancang untuk eksplorasi budaya di negara tujuan ✅ Berteman dengan pelajar internasional dan tingkatkan kemampuan komunikasi global ✅ Didampingi oleh tim EF profesional—belajar, bermain, dan eksplorasi dengan aman dan menyenangkan! Jangan lewatkan kesempatan untuk membuat liburan sekolahmu lebih bermakna! 📲 Daftar sekarang via WhatsApp: +62 811-1370-3626 #efindonesia #efstudyabroad #efhomestay #efmoment #efwintercamp2025 #studyabroad #exploretheworld #efoxford #efnewyorkcity #efsydney #wintercamp #efcambridge | C11: VIDEO | D11: REELS | E11: https://scontent-ord5-3.cdninstagram.com/o1/v/t2/f2/m86/AQPFesnUQBuEWyT9WsVKlYBZx2ox5m-1XSrELgyWhnj_IktQxqEDs0kIoy9Dw1LbOBdSaqQ84wu2Et2y8AgZtQu9MbYNMAyeO2l_RBc.mp4?_nc_cat=100&_nc_sid=5e9851&_nc_ht=scontent-ord5-3.cdninstagram.com&_nc_ohc=1cEITlqox1cQ7kNvwE4gnJN&efg=eyJ2ZW5jb2RlX3RhZyI6Inhwdl9wcm9ncmVzc2l2ZS5JTlNUQUdSQU0uQ0xJUFMuQzMuNzIwLmRhc2hfYmFzZWxpbmVfMV92MSIsInhwdl9hc3NldF9pZCI6MTM3NDE2MzQ0NDI3OTI4MywidmlfdXNlY2FzZV9pZCI6MTAwOTksImR1cmF0aW9uX3MiOjE0LCJ3YXRjaF90aW1lX3MiOjE3ODY1LCJ1cmxnZW5fc291cmNlIjoid3d3In0%3D&ccb=17-1&vs=c5585fc8bef1da26&_nc_vs=HBksFQIYUmlnX3hwdl9yZWVsc19wZXJtYW5lbnRfc3JfcHJvZC9GMzRGNDE4MjlFREY3Mjc3MzEyQzQ0NkRBQThGRDY4MV92aWRlb19kYXNoaW5pdC5tcDQVAALIARIAFQIYOnBhc3N0aHJvdWdoX2V2ZXJzdG9yZS9HQ05pRHlGZl8yZS1LTEVEQUd3eEctT3lfOHcxYnFfRUFBQUYVAgLIARIAKAAYABsCiAd1c2Vfb2lsATEScHJvZ3Jlc3NpdmVfcmVjaXBlATEVAAAm5p-tv-vy8AQVAigCQzMsF0Atu2RaHKwIGBJkYXNoX2Jhc2VsaW5lXzFfdjERAHX-B2XmnQEA&_nc_gid=abiAmay4kHKk2CacW0aRhA&edm=AL-3X8kEAAAA&_nc_zt=28&oh=00_Afc3s21kBzXWzlLJkifYwn_hJ4KGuCV-y50bg-60OnDchQ&oe=68FA6239 | F11: https://scontent-ord5-1.cdninstagram.com/v/t51.71878-15/556401937_1155941619743125_8260388531308417562_n.jpg?stp=dst-jpg_e35_tt6&_nc_cat=111&ccb=1-7&_nc_sid=18de74&efg=eyJlZmdfdGFnIjoiQ0xJUFMuYmVzdF9pbWFnZV91cmxnZW4uQzMifQ%3D%3D&_nc_ohc=iTEV9RerlQwQ7kNvwHQIWpF&_nc_oc=AdnDsLLSgZcpd-VWGuKE1-3cN2NDFwYHs3EITP8Mk3A4euxi60xa_RdvtMqVZoBzK3c&_nc_zt=23&_nc_ht=scontent-ord5-1.cdninstagram.com&edm=AL-3X8kEAAAA&_nc_gid=abiAmay4kHKk2CacW0aRhA&oh=00_AffxkE1JRGNdQQdu6XE6DOT-yfWnJWa3DgnZFKQCT-yxdw&oe=68FE5B4C | G11: https://www.instagram.com/reel/DPOOZ5IkTGg/ | H11: 2025-09-30T10:01:03+0000 | I11: 87 | J11: 0 | K11: =LEN(B11) -> 825 | L11: =(DATEVALUE(LEFT(H11,10))+TIMEVALUE(MID(H11,12,8)))+(7/24) -> 45930.709 | M11: =TEXT(L11,"mmmm") -> September | N11: =VALUE(MID(H11,12,2)) -> 10 | O11: =LEN(B11)-LEN(SUBSTITUTE(B11,"#","")) -> 12
A12: 18082928722940837 | B12: Hi EFriends! Kenalan yuk sama Kak Salwa 20 tahun, yang memutuskan untuk mengembangkan potensi diri dengan ikut program Study Abroad EF selama 3 minggu di EF Australia! ✨🌍🇦🇺 Pingin kembangin potensi diri langsung di negara impianmu? Yuk, gabung program Study Abroad EF! ✨ 📲 WA: 0811-1370-3626 #efindonesia #efstudyabroad #efhomestay #efmoment #efaustralia #belajarbahasadiaustralia #efmunich #efexperience #studyabroadjourney | C12: CAROUSEL_ALBUM | D12: FEED | E12: https://scontent-ord5-2.cdninstagram.com/v/t51.82787-15/554756059_18483053509079669_7167281829466814353_n.jpg?stp=dst-jpg_e35_tt6&_nc_cat=105&ccb=1-7&_nc_sid=18de74&efg=eyJlZmdfdGFnIjoiQ0FST1VTRUxfSVRFTS5iZXN0X2ltYWdlX3VybGdlbi5DMyJ9&_nc_ohc=v3XZ-U-l7cUQ7kNvwF2AEJm&_nc_oc=AdlAe44DVOM_LNJyaUy_1utae1RI2TPXqG0W9UwpCurzEEicdXRI-MjbToiz2hjKM6Y&_nc_zt=23&_nc_ht=scontent-ord5-2.cdninstagram.com&edm=AL-3X8kEAAAA&_nc_gid=abiAmay4kHKk2CacW0aRhA&oh=00_AfdLeEIdDtnRQYfybw9u1FWChK1zXCbRCIpi9-w1mlaKDg&oe=68FE5771 | G12: https://www.instagram.com/p/DPLphg0EQmi/ | H12: 2025-09-29T10:00:05+0000 | I12: 165 | J12: 1 | K12: =LEN(B12) -> 431 | L12: =(DATEVALUE(LEFT(H12,10))+TIMEVALUE(MID(H12,12,8)))+(7/24) -> 45929.708 | M12: =TEXT(L12,"mmmm") -> September | N12: =VALUE(MID(H12,12,2)) -> 10 | O12: =LEN(B12)-LEN(SUBSTITUTE(B12,"#","")) -> 9
A13: 17945668371051847 | B13: Mau ikut belajar dan keseruan dengan vibes kota modern di musim dingin? Mending ikut keseruannya bareng EF Winter Camp 2025 di New York di bulan December 2025!! 🇺🇸🗽❄️ Pendaftaraan untuk Winter 2025 sudah dibuka! Yuk segara daftar ❄️☃️🧣✈️ Benefit ikut EF Winter Camp 2025❄️ ✅ Kegiatan seru & edukatif yang dirancang untuk eksplorasi budaya di negara tujuan ✅ Berteman dengan pelajar internasional dan tingkatkan kemampuan komunikasi global ✅ Didampingi oleh tim EF profesional—belajar, bermain, dan eksplorasi dengan aman dan menyenangkan! Jangan lewatkan kesempatan untuk membuat liburan sekolahmu lebih bermakna! 📲 Daftar sekarang via WhatsApp: +62 811-1370-3626 #efindonesia #efstudyabroad #efhomestay #efmoment #efwintercamp2025 #studyabroad #exploretheworld #efoxford #efnewyorkcity #efsydney #wintercamp #efcambridge | C13: VIDEO | D13: REELS | E13: https://scontent-ord5-2.cdninstagram.com/o1/v/t2/f2/m86/AQNwTvIrurYa96pfRCzwJ7C3HpICUk6ZFoVyn7eJQKhTxGogA70hqN_6kSetA4gA1UVWUKLEggkthVbD6rJDvcGNhShauj4_AlyRlc4.mp4?_nc_cat=103&_nc_sid=5e9851&_nc_ht=scontent-ord5-2.cdninstagram.com&_nc_ohc=rhUPd7Qm488Q7kNvwGp3ROg&efg=eyJ2ZW5jb2RlX3RhZyI6Inhwdl9wcm9ncmVzc2l2ZS5JTlNUQUdSQU0uQ0xJUFMuQzMuNzIwLmRhc2hfYmFzZWxpbmVfMV92MSIsInhwdl9hc3NldF9pZCI6MTg1MTg4MzEzOTAxOTAxMCwidmlfdXNlY2FzZV9pZCI6MTAwOTksImR1cmF0aW9uX3MiOjE2LCJ3YXRjaF90aW1lX3MiOjM4NjQ2LCJ1cmxnZW5fc291cmNlIjoid3d3In0%3D&ccb=17-1&vs=9446f4ecc699361f&_nc_vs=HBksFQIYUmlnX3hwdl9yZWVsc19wZXJtYW5lbnRfc3JfcHJvZC8zNjQzOTU3RUI1OUM2MTg2NjVGNTNBNjkxRTZBODdBQ192aWRlb19kYXNoaW5pdC5tcDQVAALIARIAFQIYOnBhc3N0aHJvdWdoX2V2ZXJzdG9yZS9HSlZJOHlDZmlkcW01YVlFQUNRT2t2WkxTakozYnFfRUFBQUYVAgLIARIAKAAYABsCiAd1c2Vfb2lsATEScHJvZ3Jlc3NpdmVfcmVjaXBlATEVAAAmhMTVyuSRygYVAigCQzMsF0AwMzMzMzMzGBJkYXNoX2Jhc2VsaW5lXzFfdjERAHX-B2XmnQEA&_nc_gid=abiAmay4kHKk2CacW0aRhA&edm=AL-3X8kEAAAA&_nc_zt=28&oh=00_AfcdZuTEn9HAMYXFW-y_1hQHKf_whBr13Ag1sP2IIzpoqA&oe=68FA5D08 | F13: https://scontent-ord5-1.cdninstagram.com/v/t51.71878-15/554304200_1233814298512325_7824129404000672193_n.jpg?stp=dst-jpg_e35_tt6&_nc_cat=108&ccb=1-7&_nc_sid=18de74&efg=eyJlZmdfdGFnIjoiQ0xJUFMuYmVzdF9pbWFnZV91cmxnZW4uQzMifQ%3D%3D&_nc_ohc=4VP8GZpM7kAQ7kNvwGf4_U4&_nc_oc=AdlVqUzdY0Y6ml3yDVW_tnIn0Lk99gyrHGxMf6nBJtrZZOAsEWWfxUJR7a7ym7ZSgaA&_nc_zt=23&_nc_ht=scontent-ord5-1.cdninstagram.com&edm=AL-3X8kEAAAA&_nc_gid=abiAmay4kHKk2CacW0aRhA&oh=00_AffykkXQvTzkffVqLp2XTOg2bx5vF3U99tHYIjZugVcV6A&oe=68FE6B60 | G13: https://www.instagram.com/reel/DPD7VwCEfEK/ | H13: 2025-09-26T10:02:09+0000 | I13: 379 | J13: 0 | K13: =LEN(B13) -> 831 | L13: =(DATEVALUE(LEFT(H13,10))+TIMEVALUE(MID(H13,12,8)))+(7/24) -> 45926.71 | M13: =TEXT(L13,"mmmm") -> September | N13: =VALUE(MID(H13,12,2)) -> 10 | O13: =LEN(B13)-LEN(SUBSTITUTE(B13,"#","")) -> 12
A14: 18061735106093266 | B14: Kalo kamu lebih cocok ke negara apa nih?🤔🌎✨ Atau ke negara manapun bareng EF terus belajar bahasa di salah satu dari 50+ EF School yang tersebar di berbagai negara dan 10 pilihan bahasa!🚀✨ Ingin wujudkan mimpi Study Abroad mu bareng EF? Jadikan liburan mu jadi lebih seru, bermanfaat dan tak terlupakan bareng EF!📚✨ 📩 Konsultasi sekarang via DM atau WA: 0811-1370-3626 #efindonesia #efstudyabroad #efhomestay #efmoment #studyabroad #travel #EF #studyabroad | C14: CAROUSEL_ALBUM | D14: FEED | E14: https://scontent-ord5-3.cdninstagram.com/v/t51.82787-15/553152841_18481726327079669_736399599222292130_n.jpg?stp=dst-jpg_e35_tt6&_nc_cat=107&ccb=1-7&_nc_sid=18de74&efg=eyJlZmdfdGFnIjoiQ0FST1VTRUxfSVRFTS5iZXN0X2ltYWdlX3VybGdlbi5DMyJ9&_nc_ohc=uDi3-TaRjl8Q7kNvwEDQJ3n&_nc_oc=AdnP9Nur3lg9MC1CcZYzTNqsz_ONy6NiZRgB97EEyssaz5UT_9rr2QPBGOFu5hWA6Ow&_nc_zt=23&_nc_ht=scontent-ord5-3.cdninstagram.com&edm=AL-3X8kEAAAA&_nc_gid=abiAmay4kHKk2CacW0aRhA&oh=00_Afc6amHYXlsF4q57OcDT_ubsz8T2qJZyeHm9l526NbWQFA&oe=68FE6D81 | G14: https://www.instagram.com/p/DO8NoAxkTo7/ | H14: 2025-09-23T10:07:42+0000 | I14: 497 | J14: 0 | K14: =LEN(B14) -> 465 | L14: =(DATEVALUE(LEFT(H14,10))+TIMEVALUE(MID(H14,12,8)))+(7/24) -> 45923.714 | M14: =TEXT(L14,"mmmm") -> September | N14: =VALUE(MID(H14,12,2)) -> 10 | O14: =LEN(B14)-LEN(SUBSTITUTE(B14,"#","")) -> 8
A15: 18063170114370888 | B15: Study Abroad bareng EF gaperlu tunggu kuliah lho! EF punya program Study Abroad khusus Junior🤩🌎✨ Di EF Homestay, kamu bisa: ✅ Belajar langsung sama native speakers di kelas interaktif ✅ Tinggal bareng keluarga lokal yang ramah ✅ Explore budaya baru setiap hari ✈️ Ikut EF Homestay Group ke Isle of Wight, New York & Gold Coast sekarang dan dapatkan promo menarik! 🌍 📩 Konsultasi sekarang via DM atau WA: 0811-1370-3626 #efindonesia #efstudyabroad #efhomestay #efmoment #studyabroad #travel | C15: CAROUSEL_ALBUM | D15: FEED | E15: https://scontent-ord5-3.cdninstagram.com/v/t51.82787-15/551317697_18481496080079669_5731971125686815101_n.jpg?stp=dst-jpg_e35_tt6&_nc_cat=100&ccb=1-7&_nc_sid=18de74&efg=eyJlZmdfdGFnIjoiQ0FST1VTRUxfSVRFTS5iZXN0X2ltYWdlX3VybGdlbi5DMyJ9&_nc_ohc=BwSYQE-0NxUQ7kNvwGjmc__&_nc_oc=Adln4enbjLzAzZtw6Y1VPUXmPGEv4uP70GhuLxzScj5zV2iD0GDANFL6-Jf5BGLR8H4&_nc_zt=23&_nc_ht=scontent-ord5-3.cdninstagram.com&edm=AL-3X8kEAAAA&_nc_gid=abiAmay4kHKk2CacW0aRhA&oh=00_AffPAGy55eT331Qv7-0Q-WkQK-iIikHFkQnougSw86gwTg&oe=68FE73A9 | G15: https://www.instagram.com/p/DO5vFPnEbTw/ | H15: 2025-09-22T11:02:20+0000 | I15: 170 | J15: 0 | K15: =LEN(B15) -> 497 | L15: =(DATEVALUE(LEFT(H15,10))+TIMEVALUE(MID(H15,12,8)))+(7/24) -> 45922.752 | M15: =TEXT(L15,"mmmm") -> September | N15: =VALUE(MID(H15,12,2)) -> 11 | O15: =LEN(B15)-LEN(SUBSTITUTE(B15,"#","")) -> 6
A16: 17893214523319795 | B16: 1 minggu di London bareng EF aja seru banget apalagi 2 minggu!🤩🇬🇧✨ Pingin bikin liburan akhir tahun lebih seru dan tetap produktif? Yuk! Ikut EF Winter Camp 2025 dan dapetin benefit-benefit berikut: ✅ Belajar langsung sama native speakers di kelas interaktif ✅ Tinggal bareng keluarga lokal yang ramah ✅ Explore budaya baru setiap hari ✈️ Belajar + liburan seru = pengalaman tak terlupakan! 🌍 📩 Konsultasi sekarang via DM atau WA: 0811-1370-3626 #efindonesia #efstudyabroad #efhomestay #efmoment #studyabroad #travel #london | C16: VIDEO | D16: REELS | E16: https://scontent-ord5-2.cdninstagram.com/o1/v/t2/f2/m86/AQPj9YlOQabl0YRoyF0Hc5lzz1Nfd1yxusRFnbJRKKdaSQ6PACQ4voNc72e4ZTQMzfipw2sDz49Gv4kHmNrVKuFRurb4RGHzVmu_0pU.mp4?_nc_cat=110&_nc_sid=5e9851&_nc_ht=scontent-ord5-2.cdninstagram.com&_nc_ohc=7M8vn7RWxy0Q7kNvwHRX-ML&efg=eyJ2ZW5jb2RlX3RhZyI6Inhwdl9wcm9ncmVzc2l2ZS5JTlNUQUdSQU0uQ0xJUFMuQzMuNzIwLmRhc2hfYmFzZWxpbmVfMV92MSIsInhwdl9hc3NldF9pZCI6NjQ2NjUyMDcxNTAwNDkzLCJ2aV91c2VjYXNlX2lkIjoxMDA5OSwiZHVyYXRpb25fcyI6MTMsIndhdGNoX3RpbWVfcyI6NTgzOSwidXJsZ2VuX3NvdXJjZSI6Ind3dyJ9&ccb=17-1&vs=94c464f43572b4fe&_nc_vs=HBksFQIYUmlnX3hwdl9yZWVsc19wZXJtYW5lbnRfc3JfcHJvZC83QjRBMTYzQzBBMThEMzAyMjY1OTMxODk5NjIyM0E4NV92aWRlb19kYXNoaW5pdC5tcDQVAALIARIAFQIYOnBhc3N0aHJvdWdoX2V2ZXJzdG9yZS9HS1Vac1NBSjBubm9hZDhDQU9nc0dmQmZjZ3NVYnFfRUFBQUYVAgLIARIAKAAYABsCiAd1c2Vfb2lsATEScHJvZ3Jlc3NpdmVfcmVjaXBlATEVAAAmmuuesI2IpgIVAigCQzMsF0Ar3bItDlYEGBJkYXNoX2Jhc2VsaW5lXzFfdjERAHX-B2XmnQEA&_nc_gid=abiAmay4kHKk2CacW0aRhA&edm=AL-3X8kEAAAA&_nc_zt=28&oh=00_AffdcZOxOSGQ1I1c6LDGAsPBNMgflOtBn-wtoIHePv10CA&oe=68FA599F | F16: https://scontent-ord5-2.cdninstagram.com/v/t51.71878-15/550061460_1999842570848374_6173619981317349675_n.jpg?stp=dst-jpg_e35_tt6&_nc_cat=102&ccb=1-7&_nc_sid=18de74&efg=eyJlZmdfdGFnIjoiQ0xJUFMuYmVzdF9pbWFnZV91cmxnZW4uQzMifQ%3D%3D&_nc_ohc=Teft1v5GOfoQ7kNvwFKnDtZ&_nc_oc=AdmTMLLP02LHbTLcXwIadxj-Y_rPd_b9meFs5BDuw7ewC4sq3JsyvSlWkXpwl5Zahng&_nc_zt=23&_nc_ht=scontent-ord5-2.cdninstagram.com&edm=AL-3X8kEAAAA&_nc_gid=abiAmay4kHKk2CacW0aRhA&oh=00_Afdm0w4TrPz5JjLLj4Ku8Nm8vcSs52QsjCYN4zgh48QClQ&oe=68FE5001 | G16: https://www.instagram.com/reel/DOvT35XEQq3/ | H16: 2025-09-18T10:00:06+0000 | I16: 129 | J16: 0 | K16: =LEN(B16) -> 534 | L16: =(DATEVALUE(LEFT(H16,10))+TIMEVALUE(MID(H16,12,8)))+(7/24) -> 45918.708 | M16: =TEXT(L16,"mmmm") -> September | N16: =VALUE(MID(H16,12,2)) -> 10 | O16: =LEN(B16)-LEN(SUBSTITUTE(B16,"#","")) -> 7
A17: 18063589079460007 | B17: EF Homestay Group : Super Duper Good Program!🤩🌎✨ Hi EFriends! Kali ini EFriends Gold Coast mau sharing nih pengalaman ikut program EF Summer Camp 2025. Meskipun di umur nya yang masih kecil, mereka berani lo ambil langkah besar buat ke luar negeri ga sama orang tua!🚀✨ Pingin ke luar negeri bareng temen-temen baru di usia muda seperti mereka? Yuk! Isi liburan sekolah mu dengan EF Winter Camp 2025 di tanggal December 2025 - Januari 2026🌎❄️✨ 📲 Hubungi kami: 0811-1370-3626 #efindonesia #efstudyabroad #efhomestay #efmoment | C17: VIDEO | D17: REELS | E17: https://scontent-ord5-3.cdninstagram.com/o1/v/t2/f2/m86/AQMUMsybDILEcK-hyfYBZgmr0Zi_iJ1K4-wXBIb-_FZNb39QeJS5FLe1D1sc8ejqAGQHJnZoCyGnpgvVBkt2jFbKB7Ph2DXKZzNHnF0.mp4?_nc_cat=107&_nc_sid=5e9851&_nc_ht=scontent-ord5-3.cdninstagram.com&_nc_ohc=RasfdK808ZYQ7kNvwFXZ_PX&efg=eyJ2ZW5jb2RlX3RhZyI6Inhwdl9wcm9ncmVzc2l2ZS5JTlNUQUdSQU0uQ0xJUFMuQzMuNzIwLmRhc2hfYmFzZWxpbmVfMV92MSIsInhwdl9hc3NldF9pZCI6NjUxMjIyNDI0Njk2NjEzLCJ2aV91c2VjYXNlX2lkIjoxMDA5OSwiZHVyYXRpb25fcyI6NjAsIndhdGNoX3RpbWVfcyI6NzQ0MSwidXJsZ2VuX3NvdXJjZSI6Ind3dyJ9&ccb=17-1&vs=8afdcb6410589c1f&_nc_vs=HBksFQIYUmlnX3hwdl9yZWVsc19wZXJtYW5lbnRfc3JfcHJvZC80NjQyMUQyODY4RDM4Q0JERUZBOEJDRUE1NTMxOUM4Nl92aWRlb19kYXNoaW5pdC5tcDQVAALIARIAFQIYOnBhc3N0aHJvdWdoX2V2ZXJzdG9yZS9HRUk0bnlDTnMyVzMtZ0FFQUowZ0tSWFBMTjE2YnFfRUFBQUYVAgLIARIAKAAYABsCiAd1c2Vfb2lsATEScHJvZ3Jlc3NpdmVfcmVjaXBlATEVAAAmytzZlJGSqAIVAigCQzMsF0BOHdLxqfvnGBJkYXNoX2Jhc2VsaW5lXzFfdjERAHX-B2XmnQEA&_nc_gid=abiAmay4kHKk2CacW0aRhA&edm=AL-3X8kEAAAA&_nc_zt=28&oh=00_AfeKZUiMcH4M0NcGFB20K0in2SdDUvSWn_6LXSVPGFp01Q&oe=68FA85F8 | F17: https://scontent-ord5-3.cdninstagram.com/v/t51.82787-15/549290305_18480290230079669_875461199564650664_n.jpg?stp=dst-jpg_e35_tt6&_nc_cat=100&ccb=1-7&_nc_sid=18de74&efg=eyJlZmdfdGFnIjoiQ0xJUFMuYmVzdF9pbWFnZV91cmxnZW4uQzMifQ%3D%3D&_nc_ohc=R-ita2oiFjEQ7kNvwFg8MP7&_nc_oc=Adnvl8js8tMf3GeXXLRgDDkTnJQsjXftaTi7OElzohqgOSR0xO1_8May9U_CZOdNrMQ&_nc_zt=23&_nc_ht=scontent-ord5-3.cdninstagram.com&edm=AL-3X8kEAAAA&_nc_gid=abiAmay4kHKk2CacW0aRhA&oh=00_AfeA-W8lpLmqJXvhp_NiT-e4L9kDQgv6eCZ0uvbMFJQLUQ&oe=68FE7DF4 | G17: https://www.instagram.com/reel/DOqK6sLkQtQ/ | H17: 2025-09-16T10:00:04+0000 | I17: 96 | J17: 0 | K17: =LEN(B17) -> 532 | L17: =(DATEVALUE(LEFT(H17,10))+TIMEVALUE(MID(H17,12,8)))+(7/24) -> 45916.708 | M17: =TEXT(L17,"mmmm") -> September | N17: =VALUE(MID(H17,12,2)) -> 10 | O17: =LEN(B17)-LEN(SUBSTITUTE(B17,"#","")) -> 4
A18: 18072575750177618 | B18: Born to say “Selamat Pagi”. Living the dream, saying “Good Morning” With EF!🌎✨ EF bukan cuma belajar Bahasa Inggris, kamu juga belajar bahasa lainnya seperti Jepang, Jerman, Spanyol dan lain-lain di negaranya langsung!🤩✨ Ingin wujudkan mimpi Study Abroad mu bareng EF? Jadikan liburan sekolah mu lebih seru, bermanfaat, dan tak terlupakan bersama EF! 📚 📱 WA: 0811-1370-3626 #efindonesia #efstudyabroad #efhomestay #efoxford #efmoment #EF #efjapan #efwintercamp2025 #studyabroad #memories | C18: CAROUSEL_ALBUM | D18: FEED | E18: https://scontent-ord5-3.cdninstagram.com/v/t51.82787-15/549150118_18480142441079669_5211069083739971719_n.jpg?stp=dst-jpg_e35_tt6&_nc_cat=107&ccb=1-7&_nc_sid=18de74&efg=eyJlZmdfdGFnIjoiQ0FST1VTRUxfSVRFTS5iZXN0X2ltYWdlX3VybGdlbi5DMyJ9&_nc_ohc=fVYcxewo4KUQ7kNvwFGfloN&_nc_oc=AdklA5gnKeEUjLlK8z-rOwITbBss9yi0gOelJFQgkwv7YsPue8tm6hXGhSD9dSh1fCM&_nc_zt=23&_nc_ht=scontent-ord5-3.cdninstagram.com&edm=AL-3X8kEAAAA&_nc_gid=abiAmay4kHKk2CacW0aRhA&oh=00_AfcqJ4SVn9t7Jl0UwHqXz3RRg8RHJd-7gtEW_4_CoTPAKQ&oe=68FE5924 | G18: https://www.instagram.com/p/DOnm5_RkQxM/ | H18: 2025-09-15T10:04:34+0000 | I18: 17327 | J18: 21 | K18: =LEN(B18) -> 495 | L18: =(DATEVALUE(LEFT(H18,10))+TIMEVALUE(MID(H18,12,8)))+(7/24) -> 45915.712 | M18: =TEXT(L18,"mmmm") -> September | N18: =VALUE(MID(H18,12,2)) -> 10 | O18: =LEN(B18)-LEN(SUBSTITUTE(B18,"#","")) -> 10
A19: 18061616201603100 | B19: This is your sign to visit Gold Coast, Australia this winter!!!🇦🇺 Liburan akhir tahun kali ini jangan dirumah aja, coba pengalaman seru belajar bahasa Inggris sambil nikmatin pantai dan city life yang ikonik di Gold Coast 🌊✨ Di EF Homestay, kamu bisa: ✅ Belajar langsung sama native speakers di kelas interaktif ✅ Tinggal bareng keluarga lokal yang ramah ✅ Explore budaya baru setiap hari ✈️ Belajar + liburan seru = pengalaman tak terlupakan! 🌍 📩 Konsultasi sekarang via DM atau WA: 0811-1370-3626 #efindonesia #efstudyabroad #efhomestay #efmoment #studyabroad #travel #goldcoast | C19: VIDEO | D19: REELS | E19: https://scontent-ord5-3.cdninstagram.com/o1/v/t2/f2/m86/AQNLg40_USCyu61EbjteypK_-i-wZe0bzrWpNW1AqyRwranbt-qb3rYjYUhBeU0fjy9vIdBX79tlmsgY7JKwbUUio8dz_RH_XR969SA.mp4?_nc_cat=107&_nc_sid=5e9851&_nc_ht=scontent-ord5-3.cdninstagram.com&_nc_ohc=SRdJI0Raj20Q7kNvwFKlMeC&efg=eyJ2ZW5jb2RlX3RhZyI6Inhwdl9wcm9ncmVzc2l2ZS5JTlNUQUdSQU0uQ0xJUFMuQzMuNzIwLmRhc2hfYmFzZWxpbmVfMV92MSIsInhwdl9hc3NldF9pZCI6MTA5Mjc1MjM4OTUwNTUzOSwidmlfdXNlY2FzZV9pZCI6MTAwOTksImR1cmF0aW9uX3MiOjIyLCJ3YXRjaF90aW1lX3MiOjYyNDUsInVybGdlbl9zb3VyY2UiOiJ3d3cifQ%3D%3D&ccb=17-1&vs=d4471f2c1289c84e&_nc_vs=HBksFQIYUmlnX3hwdl9yZWVsc19wZXJtYW5lbnRfc3JfcHJvZC9GMDQ3NTg2MjQwQzc2MDE0NkFFRDcwQzc5QkEwNEZCOF92aWRlb19kYXNoaW5pdC5tcDQVAALIARIAFQIYOnBhc3N0aHJvdWdoX2V2ZXJzdG9yZS9HQUZSbUNERGJfN25RdmNHQU0tRzBrQmppN04yYnFfRUFBQUYVAgLIARIAKAAYABsCiAd1c2Vfb2lsATEScHJvZ3Jlc3NpdmVfcmVjaXBlATEVAAAmhoiI4Mf28AMVAigCQzMsF0A2d0vGp--eGBJkYXNoX2Jhc2VsaW5lXzFfdjERAHX-B2XmnQEA&_nc_gid=abiAmay4kHKk2CacW0aRhA&edm=AL-3X8kEAAAA&_nc_zt=28&oh=00_AfeOWpYh3ib_kngvLi4041jvfn6UDG-LXpBbP-ye0CY3tA&oe=68FA6D90 | F19: https://scontent-ord5-1.cdninstagram.com/v/t51.71878-15/548081592_1109242534609390_5628190769522791099_n.jpg?stp=dst-jpg_e35_tt6&_nc_cat=111&ccb=1-7&_nc_sid=18de74&efg=eyJlZmdfdGFnIjoiQ0xJUFMuYmVzdF9pbWFnZV91cmxnZW4uQzMifQ%3D%3D&_nc_ohc=mPOABilXMrYQ7kNvwGGLImJ&_nc_oc=AdlLuA4mjNe7EaRA_aLyCVyPUGHPG7PDcsHAPEPpsGvIDrs_jqJs520-1Mco6T96X-w&_nc_zt=23&_nc_ht=scontent-ord5-1.cdninstagram.com&edm=AL-3X8kEAAAA&_nc_gid=abiAmay4kHKk2CacW0aRhA&oh=00_AfeIthH7HFBsxoFHKe9oz7div9wPpLNYM-MWYgY8kDdTag&oe=68FE72EC | G19: https://www.instagram.com/reel/DOf3ztEkfIy/ | H19: 2025-09-12T10:00:08+0000 | I19: 75 | J19: 2 | K19: =LEN(B19) -> 590 | L19: =(DATEVALUE(LEFT(H19,10))+TIMEVALUE(MID(H19,12,8)))+(7/24) -> 45912.708 | M19: =TEXT(L19,"mmmm") -> September | N19: =VALUE(MID(H19,12,2)) -> 10 | O19: =LEN(B19)-LEN(SUBSTITUTE(B19,"#","")) -> 7
A20: 18095844055579762 | B20: Hi EFriends! Kenalan yuk sama Kak Amik, 20 tahun lebih, yang memutuskan buat ikut program Study Abroad EF selama 3 minggu di EF Oxford! 🇬🇧✨ Kerennya lagi, selama di UK Kak Amik bisa ketemu banyak teman dari berbagai negara, ikut belajar langsung di EF Oxford, dan tinggal bareng host family super baik yang bahkan kasih laundry gratis & masakan enak setiap hari!🥘🤩✨ Pingin juga upgrade skill bahasa Inggris sambil explore budaya di negara impianmu? Yuk, gabung program Study Abroad EF! ✨ 📲 WA: 0811-1370-3626 #efindonesia #efstudyabroad #efhomestay #efmoment #efoxford #belajarbahasasinggris #efexperience #studyabroadjourney | C20: CAROUSEL_ALBUM | D20: FEED | E20: https://scontent-ord5-1.cdninstagram.com/v/t51.82787-15/544125174_18479345491079669_833904181575477834_n.jpg?stp=dst-jpg_e35_tt6&_nc_cat=111&ccb=1-7&_nc_sid=18de74&efg=eyJlZmdfdGFnIjoiQ0FST1VTRUxfSVRFTS5iZXN0X2ltYWdlX3VybGdlbi5DMyJ9&_nc_ohc=kiJDdmSQ7nEQ7kNvwH6Qgdb&_nc_oc=AdnZvN1RiU7WJYhNocmPTZ3m-v3DBvJ7khuIavf7MfgChgpRHtAdPTJ0YQYsPto4ooQ&_nc_zt=23&_nc_ht=scontent-ord5-1.cdninstagram.com&edm=AL-3X8kEAAAA&_nc_gid=abiAmay4kHKk2CacW0aRhA&oh=00_AfcmTATI0DLyZlKPDqQCXyHmY3Iimchj5ePK-_U29uboaQ&oe=68FE60B1 | G20: https://www.instagram.com/p/DOaudVpkQra/ | H20: 2025-09-10T10:00:26+0000 | I20: 98 | J20: 2 | K20: =LEN(B20) -> 634 | L20: =(DATEVALUE(LEFT(H20,10))+TIMEVALUE(MID(H20,12,8)))+(7/24) -> 45910.709 | M20: =TEXT(L20,"mmmm") -> September | N20: =VALUE(MID(H20,12,2)) -> 10 | O20: =LEN(B20)-LEN(SUBSTITUTE(B20,"#","")) -> 8
A21: 18016902011769048 | B21: Buat liburan akhir tahunmu tak terlupakan dengan EF Study Abroad Program di negara impian mu dengan diskon special sebesar 20%!🌎🤩✨ Jelajahi destinasi menarik di seluruh dunia, tingkatkan kemampuan bahasa, pelajari budaya baru, dan ciptakan kenangan seumur hidup bersama teman-teman dari berbagai negara.🛩️🌎 📌 Limited Seats — daftar sebelum 30 September 2025 untuk amankan tempatmu dan dapatkan diskon spesial hingga 20%. Yuk! Daftar dan dapatkan diskon sekarang di link berikut https://bit.ly/EFPromoSept25 #efindonesia #efstudyabroad #efhomestay #efmoment | C21: CAROUSEL_ALBUM | D21: FEED | E21: https://scontent-ord5-3.cdninstagram.com/v/t51.82787-15/542745578_18479200561079669_3676828075492279821_n.jpg?stp=dst-jpg_e35_tt6&_nc_cat=100&ccb=1-7&_nc_sid=18de74&efg=eyJlZmdfdGFnIjoiQ0FST1VTRUxfSVRFTS5iZXN0X2ltYWdlX3VybGdlbi5DMyJ9&_nc_ohc=uMkWDrv48GwQ7kNvwEK0S9n&_nc_oc=Adkkmox2ce-bE-zQ7XfZ6xostCS55xccgg7MkTTHkb_CvrS2_3H2gm_BFm3rnaeQr9Y&_nc_zt=23&_nc_ht=scontent-ord5-3.cdninstagram.com&edm=AL-3X8kEAAAA&_nc_gid=abiAmay4kHKk2CacW0aRhA&oh=00_Afdb6D5LC2SEVL-zSrwiG66Y1bfH8eJFY8pq6BD-ZCr7kQ&oe=68FE691A | G21: https://www.instagram.com/p/DOYLbAwEVuu/ | H21: 2025-09-09T10:15:48+0000 | I21: 23 | J21: 2 | K21: =LEN(B21) -> 565 | L21: =(DATEVALUE(LEFT(H21,10))+TIMEVALUE(MID(H21,12,8)))+(7/24) -> 45909.719 | M21: =TEXT(L21,"mmmm") -> September | N21: =VALUE(MID(H21,12,2)) -> 10 | O21: =LEN(B21)-LEN(SUBSTITUTE(B21,"#","")) -> 4
A22: 18110399485554766 | B22: Pingin kuliah di luar negerj tapi bingung harus mulai dari mana?🤔🎓 EF University Preparation bakal bantu seluruh persiapan mu buat masuk ke universitas impian di luar negeri langsung di EF Campus negara tujuan lho! 🏛️🎓🌎 Pst! Ada jaminan 100% kamu bakal diterima di universitas luar negeri. Tunggu apa lagi, Yuk! Daftarkan dirimu dan mulai persiapan mulai dari sekarang!🚀✨ Hubungi kami: 0811-1370-3626 #efindonesia #efstudyabroad #efhomestay #efmoment | C22: VIDEO | D22: REELS | E22: https://scontent-ord5-1.cdninstagram.com/o1/v/t2/f2/m86/AQOVqxL7cVJkpJia4O2BC9pM0_PpZ2su7n_-7EpYdePFAYxID0x_gvv4NHDze6lcY6anX0GFG3GW34DOb2cSuU_tP7EY6HhqXoe-Sx8.mp4?_nc_cat=111&_nc_sid=5e9851&_nc_ht=scontent-ord5-1.cdninstagram.com&_nc_ohc=2HD2HkZY5OAQ7kNvwG1gBWY&efg=eyJ2ZW5jb2RlX3RhZyI6Inhwdl9wcm9ncmVzc2l2ZS5JTlNUQUdSQU0uQ0xJUFMuQzMuNzIwLmRhc2hfYmFzZWxpbmVfMV92MSIsInhwdl9hc3NldF9pZCI6MTI4NzE0MTU1MzEwNDU1MSwidmlfdXNlY2FzZV9pZCI6MTAwOTksImR1cmF0aW9uX3MiOjEzLCJ3YXRjaF90aW1lX3MiOjI0MTUsInVybGdlbl9zb3VyY2UiOiJ3d3cifQ%3D%3D&ccb=17-1&vs=9a01509d27254a97&_nc_vs=HBksFQIYUmlnX3hwdl9yZWVsc19wZXJtYW5lbnRfc3JfcHJvZC8wQjRGM0YwQjg2QTJFODk4MzY5RUQ2QTM3REEyMzFBQ192aWRlb19kYXNoaW5pdC5tcDQVAALIARIAFQIYOnBhc3N0aHJvdWdoX2V2ZXJzdG9yZS9HTTNZZUNCSFpkVUFpQlVFQUZoaUNpd2Y5cWNmYnFfRUFBQUYVAgLIARIAKAAYABsCiAd1c2Vfb2lsATEScHJvZ3Jlc3NpdmVfcmVjaXBlATEVAAAmzprj8L-pyQQVAigCQzMsF0ArEOVgQYk3GBJkYXNoX2Jhc2VsaW5lXzFfdjERAHX-B2XmnQEA&_nc_gid=abiAmay4kHKk2CacW0aRhA&edm=AL-3X8kEAAAA&_nc_zt=28&oh=00_Aff4kJcuPno2S4rLKnMZTqtFPoaaoyfgIx1jwXLpUhzl_w&oe=68FA81C8 | F22: https://scontent-ord5-3.cdninstagram.com/v/t51.71878-15/545135017_1454155085815222_3727800789344649712_n.jpg?stp=dst-jpg_e35_tt6&_nc_cat=100&ccb=1-7&_nc_sid=18de74&efg=eyJlZmdfdGFnIjoiQ0xJUFMuYmVzdF9pbWFnZV91cmxnZW4uQzMifQ%3D%3D&_nc_ohc=R1AyrgBv9IEQ7kNvwEdtxJz&_nc_oc=AdmePhRiZcZ0fIouggnXn-Zu5jLe8-lrDX7JXzGjqaTYPCWkqOgMfRUE-bozPyGPedU&_nc_zt=23&_nc_ht=scontent-ord5-3.cdninstagram.com&edm=AL-3X8kEAAAA&_nc_gid=abiAmay4kHKk2CacW0aRhA&oh=00_AffbenZg94TXYIf-vyc2GBTytW8X5eedg5hias_M70bbKg&oe=68FE60A3 | G22: https://www.instagram.com/reel/DOVkhYpEU__/ | H22: 2025-09-08T10:00:02+0000 | I22: 39 | J22: 2 | K22: =LEN(B22) -> 461 | L22: =(DATEVALUE(LEFT(H22,10))+TIMEVALUE(MID(H22,12,8)))+(7/24) -> 45908.708 | M22: =TEXT(L22,"mmmm") -> September | N22: =VALUE(MID(H22,12,2)) -> 10 | O22: =LEN(B22)-LEN(SUBSTITUTE(B22,"#","")) -> 4
A23: 18338971558207778 | B23: Liburan musim dingin tak terlupakan bareng EF❄️🌎✨ Pingin buat liburan musim dingin mu lebih seru dan produktif bareng temen-temen baru di luar negeri? Yuk! Konsultasi sekarang🤩✨ 📲 Hubungi kami: 0811-1370-3626 #efindonesia #efstudyabroad #efhomestay #efmoment | C23: CAROUSEL_ALBUM | D23: FEED | E23: https://scontent-ord5-3.cdninstagram.com/v/t51.82787-15/542219919_18478286539079669_2984504348115030469_n.jpg?stp=dst-jpg_e35_tt6&_nc_cat=100&ccb=1-7&_nc_sid=18de74&efg=eyJlZmdfdGFnIjoiQ0FST1VTRUxfSVRFTS5iZXN0X2ltYWdlX3VybGdlbi5DMyJ9&_nc_ohc=amWSK6-zExYQ7kNvwFOyePu&_nc_oc=AdnuWIGS0Y26gIqM3ck9k9IGcfB3N9Bo-7ifVNZoMCdv22OrvXROy3P7j1CukqfrC9w&_nc_zt=23&_nc_ht=scontent-ord5-3.cdninstagram.com&edm=AL-3X8kEAAAA&_nc_gid=abiAmay4kHKk2CacW0aRhA&oh=00_Afc0cXeLNwKLQo3NQCU62wktA1D5ybvz3ZxyTYb-uIHW3A&oe=68FE48D6 | G23: https://www.instagram.com/p/DOItWSLESbI/ | H23: 2025-09-03T10:04:24+0000 | I23: 499 | J23: 2 | K23: =LEN(B23) -> 264 | L23: =(DATEVALUE(LEFT(H23,10))+TIMEVALUE(MID(H23,12,8)))+(7/24) -> 45903.711 | M23: =TEXT(L23,"mmmm") -> September | N23: =VALUE(MID(H23,12,2)) -> 10 | O23: =LEN(B23)-LEN(SUBSTITUTE(B23,"#","")) -> 4
A24: 18046464653322168 | B24: EFriends Oxford mau sharing nih pengalaman-pengalaman serunya selama 3 minggu di Oxford!🇬🇧✨ Belajar bahasa Inggris langsung di kota universitas paling ikonik di dunia, sambil explore negara dan ketemu teman baru dari berbagai negara🛩️🌎✨ Kamu juga bisa rasain serunya belajar sambil liburan bareng EF & EFriends lainnya!🤩✨ 📲 Hubungi kami: 0811-1370-3626 #efindonesia #efstudyabroad #efhomestay #efmoment | C24: VIDEO | D24: REELS | E24: https://scontent-ord5-3.cdninstagram.com/o1/v/t2/f2/m86/AQOuXLW-3xATagjuRlYPg6Z46ZJUm1LkVja32glTwOxXRJ-64JGCDQiTdEYJmYYpFKgIGN2sXPtRINCBKEQ0zvcnjUqLcadR9xTipow.mp4?_nc_cat=106&_nc_sid=5e9851&_nc_ht=scontent-ord5-3.cdninstagram.com&_nc_ohc=UFRfbDvUSuIQ7kNvwHusYdf&efg=eyJ2ZW5jb2RlX3RhZyI6Inhwdl9wcm9ncmVzc2l2ZS5JTlNUQUdSQU0uQ0xJUFMuQzMuNzIwLmRhc2hfYmFzZWxpbmVfMV92MSIsInhwdl9hc3NldF9pZCI6MjQzODg5OTQ4NjQwOTE5MTMsInZpX3VzZWNhc2VfaWQiOjEwMDk5LCJkdXJhdGlvbl9zIjo1OSwid2F0Y2hfdGltZV9zIjoxNjI5MywidXJsZ2VuX3NvdXJjZSI6Ind3dyJ9&ccb=17-1&vs=1bd96d739fa255ea&_nc_vs=HBksFQIYUmlnX3hwdl9yZWVsc19wZXJtYW5lbnRfc3JfcHJvZC9EMjQzMTc4Q0E2MDlENTA2RTBGMTdBRUY0QjIxQkNCOV92aWRlb19kYXNoaW5pdC5tcDQVAALIARIAFQIYOnBhc3N0aHJvdWdoX2V2ZXJzdG9yZS9HSUxwR3lEdUpxRThkblVGQUo2QzBBUFBQN1phYnFfRUFBQUYVAgLIARIAKAAYABsCiAd1c2Vfb2lsATEScHJvZ3Jlc3NpdmVfcmVjaXBlATEVAAAmkszs9Kvq0lYVAigCQzMsF0BNszMzMzMzGBJkYXNoX2Jhc2VsaW5lXzFfdjERAHX-B2XmnQEA&_nc_gid=abiAmay4kHKk2CacW0aRhA&edm=AL-3X8kEAAAA&_nc_zt=28&oh=00_AfcbWVt-j7_iT4IZCFfJ3NiqrdEkVj0sKGy9XyyQgaBvkQ&oe=68FA862F | F24: https://scontent-ord5-3.cdninstagram.com/v/t51.71878-15/541777592_2532223857133377_8618708656483626474_n.jpg?stp=dst-jpg_e35_tt6&_nc_cat=106&ccb=1-7&_nc_sid=18de74&efg=eyJlZmdfdGFnIjoiQ0xJUFMuYmVzdF9pbWFnZV91cmxnZW4uQzMifQ%3D%3D&_nc_ohc=iydJvLE0PhsQ7kNvwFanhjz&_nc_oc=AdlShA71-XL_cUQmFoND9vMabCKD_kQO5mSI3hVhP4gROH_oR5RV278tK9yEyVlvRIw&_nc_zt=23&_nc_ht=scontent-ord5-3.cdninstagram.com&edm=AL-3X8kEAAAA&_nc_gid=abiAmay4kHKk2CacW0aRhA&oh=00_Afd-MVOo5BKC1bnya0eYVhQXxwSAv_6PVFBdFr6-hYK3XA&oe=68FE604A | G24: https://www.instagram.com/reel/DOGGjQskdJD/ | H24: 2025-09-02T10:00:25+0000 | I24: 446 | J24: 6 | K24: =LEN(B24) -> 412 | L24: =(DATEVALUE(LEFT(H24,10))+TIMEVALUE(MID(H24,12,8)))+(7/24) -> 45902.709 | M24: =TEXT(L24,"mmmm") -> September | N24: =VALUE(MID(H24,12,2)) -> 10 | O24: =LEN(B24)-LEN(SUBSTITUTE(B24,"#","")) -> 4
A25: 18064917034998896 | B25: Pingin belajar Bahasa asing di Luar Negeri? Bisa banget! ✨🌍 Dengan ikut program EF Study Abroad, kamu bisa belajar langsung bareng guru native speaker di luar negeri, tambah temen internasional sambil Explore dan menambah pengalaman seru di destinasi impianmu ! 🔥🎒🌎 Belajar, jalan-jalan, dan seru-seruan—semuanya dalam satu paket! 🚀💬 Siap upgrade skill bahasa kamu bareng EF? Yuk! Konsultasi sekarang! WA: 0811-1370-3626 #efindonesia #efstudyabroad #efhomestay #efmoment #EFStudyAbroad #BelajarTanpaBatas #exploretheworld | C25: VIDEO | D25: REELS | E25: https://scontent-ord5-1.cdninstagram.com/o1/v/t2/f2/m86/AQNXXxZTweJ5tJp-PxTM9o2L-sKy5_orEztGnvPnAda8n43SXX6t-mAQyir1jRcK_ugfdk8o3_LdQO3uTKTDyIBb96GuUby6gqu55-c.mp4?_nc_cat=108&_nc_sid=5e9851&_nc_ht=scontent-ord5-1.cdninstagram.com&_nc_ohc=14CzhsEXKrEQ7kNvwH5VQse&efg=eyJ2ZW5jb2RlX3RhZyI6Inhwdl9wcm9ncmVzc2l2ZS5JTlNUQUdSQU0uQ0xJUFMuQzMuNzIwLmRhc2hfYmFzZWxpbmVfMV92MSIsInhwdl9hc3NldF9pZCI6MTk0MDkzMzEyMzQxNTM2MywidmlfdXNlY2FzZV9pZCI6MTAwOTksImR1cmF0aW9uX3MiOjEyLCJ3YXRjaF90aW1lX3MiOjIzOTgsInVybGdlbl9zb3VyY2UiOiJ3d3cifQ%3D%3D&ccb=17-1&vs=22023084fc922d6d&_nc_vs=HBksFQIYUmlnX3hwdl9yZWVsc19wZXJtYW5lbnRfc3JfcHJvZC9FNTRBMjQxQTgyNDk5QjFDNDFEQ0JCOTE5MzI4N0FCN192aWRlb19kYXNoaW5pdC5tcDQVAALIARIAFQIYOnBhc3N0aHJvdWdoX2V2ZXJzdG9yZS9HSnNEUWlDVUJYbTh1Nm9DQUJ1el9Ld2FtbWtvYnFfRUFBQUYVAgLIARIAKAAYABsCiAd1c2Vfb2lsATEScHJvZ3Jlc3NpdmVfcmVjaXBlATEVAAAmhvXU1ZbR8gYVAigCQzMsF0ApZmZmZmZmGBJkYXNoX2Jhc2VsaW5lXzFfdjERAHX-B2XmnQEA&_nc_gid=abiAmay4kHKk2CacW0aRhA&edm=AL-3X8kEAAAA&_nc_zt=28&oh=00_AfdIhml4gBVuhsZEfcbjBjgTv5Qco8mHqIjfzzE3rCWW0A&oe=68FA5835 | F25: https://scontent-ord5-3.cdninstagram.com/v/t51.82787-15/539931067_18477348835079669_5582617833066727186_n.jpg?stp=dst-jpg_e35_tt6&_nc_cat=104&ccb=1-7&_nc_sid=18de74&efg=eyJlZmdfdGFnIjoiQ0xJUFMuYmVzdF9pbWFnZV91cmxnZW4uQzMifQ%3D%3D&_nc_ohc=EZO-1ViUCnQQ7kNvwGCh77U&_nc_oc=Adk2fh5j0XlhVvyBdY4rBK1HrXN0DTRJjoVQwm1Com4qJRWq4Xa0x0kM2stPJgB6GLk&_nc_zt=23&_nc_ht=scontent-ord5-3.cdninstagram.com&edm=AL-3X8kEAAAA&_nc_gid=abiAmay4kHKk2CacW0aRhA&oh=00_Afd2wLpaqXG_D5eAtNm_2Oxr9t5hiVM1ZHJBc-DwXHaHFg&oe=68FE503A | G25: https://www.instagram.com/reel/DN5PDNSEQP3/ | H25: 2025-08-28T10:00:07+0000 | I25: 167 | J25: 2 | K25: =LEN(B25) -> 531 | L25: =(DATEVALUE(LEFT(H25,10))+TIMEVALUE(MID(H25,12,8)))+(7/24) -> 45897.708 | M25: =TEXT(L25,"mmmm") -> August | N25: =VALUE(MID(H25,12,2)) -> 10 | O25: =LEN(B25)-LEN(SUBSTITUTE(B25,"#","")) -> 7
A26: 18173710936352763 | B26: 1 Hari bareng EF Malta! Seru-seruan bareng teman-teman dari berbagai negara!🌎🇲🇹✨ Mulai dari jalan-jalan di kota bersejarah Mdina yang penuh pesona, menikmati suasana autentik Rabat, sampai dibuat takjub sama pemandangan laut dengan menikmati sunset di Dingli Cliffs 🌊☀️ Pingin explore tempat indah sambil dapet pengalaman internasional bareng EF Malta? Yuk! Konsultasi sekarang🇲🇹✨ 📱 WA: 0811-1370-3626 #efindonesia #efstudyabroad #efhomestay #efmalta #efmoment #EF #studyabroad #memories #onedayinmalta | C26: VIDEO | D26: REELS | E26: https://scontent-ord5-1.cdninstagram.com/o1/v/t2/f2/m86/AQN3LA3GwcsSLgkulCYhpxWPbmMe68Y9Qbl3H16_LEWriCUkyvMxV52ajAHeKZvsHk938aGcChuRM7-4hFx7NhP6VlnKouKC1dbqF1o.mp4?_nc_cat=108&_nc_sid=5e9851&_nc_ht=scontent-ord5-1.cdninstagram.com&_nc_ohc=lCSvC11OGkQQ7kNvwH6CtGD&efg=eyJ2ZW5jb2RlX3RhZyI6Inhwdl9wcm9ncmVzc2l2ZS5JTlNUQUdSQU0uQ0xJUFMuQzMuNzIwLmRhc2hfYmFzZWxpbmVfMV92MSIsInhwdl9hc3NldF9pZCI6MTc4MDYyNDY2NTk5Mjg1NiwidmlfdXNlY2FzZV9pZCI6MTAwOTksImR1cmF0aW9uX3MiOjU2LCJ3YXRjaF90aW1lX3MiOjM1OTYsInVybGdlbl9zb3VyY2UiOiJ3d3cifQ%3D%3D&ccb=17-1&vs=f74b10ddd3e6baf4&_nc_vs=HBksFQIYUmlnX3hwdl9yZWVsc19wZXJtYW5lbnRfc3JfcHJvZC9GNzQ4QUY1OUNENjI0MDY4RjQxMEM3MjBEOTg1ODg5RF92aWRlb19kYXNoaW5pdC5tcDQVAALIARIAFQIYOnBhc3N0aHJvdWdoX2V2ZXJzdG9yZS9HQXRrR0NDTDgxX1k2dWtEQU9pRDhLTGZEZlpUYnFfRUFBQUYVAgLIARIAKAAYABsCiAd1c2Vfb2lsATEScHJvZ3Jlc3NpdmVfcmVjaXBlATEVAAAmsPqOy__dqQYVAigCQzMsF0BMQAAAAAAAGBJkYXNoX2Jhc2VsaW5lXzFfdjERAHX-B2XmnQEA&_nc_gid=abiAmay4kHKk2CacW0aRhA&edm=AL-3X8kEAAAA&_nc_zt=28&oh=00_AfdJ-8An0N-ViDuR-JrKUTgZ5y5Z2559hFUwOmBz5P14ww&oe=68FA7771 | F26: https://scontent-ord5-2.cdninstagram.com/v/t51.82787-15/539427205_18476540224079669_1421983885667747489_n.jpg?stp=dst-jpg_e35_tt6&_nc_cat=102&ccb=1-7&_nc_sid=18de74&efg=eyJlZmdfdGFnIjoiQ0xJUFMuYmVzdF9pbWFnZV91cmxnZW4uQzMifQ%3D%3D&_nc_ohc=WSDg775wDRMQ7kNvwGlBARe&_nc_oc=AdmKx2IGi9uN_hSW9-3IllFl0N0fo6pabjW3_QDoXszyNRlTxh0f8aMOp882BiG8MiQ&_nc_zt=23&_nc_ht=scontent-ord5-2.cdninstagram.com&edm=AL-3X8kEAAAA&_nc_gid=abiAmay4kHKk2CacW0aRhA&oh=00_AfcIteSV4bdp9oBHWp-vFSXxwytJZ02RtAYTfNl-PpTc8A&oe=68FE487E | G26: https://www.instagram.com/reel/DNxhjaZ4hTN/ | H26: 2025-08-25T10:35:35+0000 | I26: 55 | J26: 1 | K26: =LEN(B26) -> 514 | L26: =(DATEVALUE(LEFT(H26,10))+TIMEVALUE(MID(H26,12,8)))+(7/24) -> 45894.733 | M26: =TEXT(L26,"mmmm") -> August | N26: =VALUE(MID(H26,12,2)) -> 10 | O26: =LEN(B26)-LEN(SUBSTITUTE(B26,"#","")) -> 9
A27: 18066391904235206 | B27: Hi EFriends! Kenalan yuk sama Kak Novaristo, 18 tahun, yang memutuskan buat ikut program Study Abroad EF selama 2 minggu di EF Singapore! 🇸🇬✨ Serunya lagi, ini jadi pengalaman pertama kali Novaristo ke luar negeri sendiri lho! 🌍✈️ Pingin juga kembangin skill bahasa Inggris sambil merasakan pengalaman baru di negara impianmu? Yuk, gabung program Study Abroad EF! ✨ 📲 WA: 0811-1370-3626 #efindonesia #efstudyabroad #efhomestay #efmoment #efsingapore #belajarbahasadinggris #efexperience #studyabroadjourney | C27: CAROUSEL_ALBUM | D27: FEED | E27: https://scontent-ord5-3.cdninstagram.com/v/t51.82787-15/536676959_18475382362079669_5234293854742082913_n.jpg?stp=dst-jpg_e35_tt6&_nc_cat=107&ccb=1-7&_nc_sid=18de74&efg=eyJlZmdfdGFnIjoiQ0FST1VTRUxfSVRFTS5iZXN0X2ltYWdlX3VybGdlbi5DMyJ9&_nc_ohc=0968vOkA0SEQ7kNvwGSfZ2P&_nc_oc=AdmFx_-3ivxcZYSN2b0MLoChsusQAeVa59HaYXjezrZj5IGzy4brxggBEqUIHgkepcY&_nc_zt=23&_nc_ht=scontent-ord5-3.cdninstagram.com&edm=AL-3X8kEAAAA&_nc_gid=abiAmay4kHKk2CacW0aRhA&oh=00_AfcPHAwmCPh4dqER3uZdXFDt7AmhgQ3Cv-szmg4jZuilPQ&oe=68FE4A95 | G27: https://www.instagram.com/p/DNnPKzYS1B3/ | H27: 2025-08-21T10:05:45+0000 | I27: 86 | J27: 1 | K27: =LEN(B27) -> 514 | L27: =(DATEVALUE(LEFT(H27,10))+TIMEVALUE(MID(H27,12,8)))+(7/24) -> 45890.712 | M27: =TEXT(L27,"mmmm") -> August | N27: =VALUE(MID(H27,12,2)) -> 10 | O27: =LEN(B27)-LEN(SUBSTITUTE(B27,"#","")) -> 8
A28: 18234334672288622 | B28: Ke luar negeri makin seru kalau bareng EF!🌍🤩✨ Bukan cuma belajar bahasa Inggris, tapi juga bisa explore destinasi ikonik kayak Big Ben, London Eye, sampai Harry Potter Studio Tour 🇬🇧 EF menyediakan kelas bahasa Inggris yang interaktif dan seru, langsung bersama native speakers! Kamu juga bakal punya kesempatan kenal teman internasional dari berbagai negara, jadi pengalaman belajar kamu bakal jauh lebih berwarna 🌍✨ Yuk rasain serunya belajar sambil jalan-jalan di London! Konsultasi sekarang via DM atau WA (0811-1370-3626) 🤗 #efindonesia #efstudyabroad #efmoment #studyabroad #travel #education #london | C28: VIDEO | D28: REELS | E28: https://scontent-ord5-1.cdninstagram.com/o1/v/t2/f2/m86/AQMTRrZwqbR-7msojq2iB8EsZXHLAGTmb4unIB0jyJILRD0b1H7almoZkfcn_VC543B82nkvuV8lBAj05uZLKapaSGUZEPpyPIoeJxI.mp4?_nc_cat=111&_nc_sid=5e9851&_nc_ht=scontent-ord5-1.cdninstagram.com&_nc_ohc=y_eaZEE1FPEQ7kNvwGx3vDV&efg=eyJ2ZW5jb2RlX3RhZyI6Inhwdl9wcm9ncmVzc2l2ZS5JTlNUQUdSQU0uQ0xJUFMuQzMuNzIwLmRhc2hfYmFzZWxpbmVfMV92MSIsInhwdl9hc3NldF9pZCI6MTQ1ODE5MTIxODc5MDkzMywidmlfdXNlY2FzZV9pZCI6MTAwOTksImR1cmF0aW9uX3MiOjcsIndhdGNoX3RpbWVfcyI6Mjc3NywidXJsZ2VuX3NvdXJjZSI6Ind3dyJ9&ccb=17-1&vs=63811a0cf658f0dc&_nc_vs=HBksFQIYUmlnX3hwdl9yZWVsc19wZXJtYW5lbnRfc3JfcHJvZC8yNDRBM0YzQUYxNUI5MzNFNEM2NzdFNDI4N0QyMzNCN192aWRlb19kYXNoaW5pdC5tcDQVAALIARIAFQIYOnBhc3N0aHJvdWdoX2V2ZXJzdG9yZS9HRWFQM1I4aHRtRWtMY0lEQUVRNWgyNU1fNjU0YnFfRUFBQUYVAgLIARIAKAAYABsCiAd1c2Vfb2lsATEScHJvZ3Jlc3NpdmVfcmVjaXBlATEVAAAmqsjimfONlwUVAigCQzMsF0AcAAAAAAAAGBJkYXNoX2Jhc2VsaW5lXzFfdjERAHX-B2XmnQEA&_nc_gid=abiAmay4kHKk2CacW0aRhA&edm=AL-3X8kEAAAA&_nc_zt=28&oh=00_Afd3QCf5TkaKH-sgGAEtqZ40XkFfw4438M9lsgFARguREA&oe=68FA6928 | F28: https://scontent-ord5-3.cdninstagram.com/v/t51.71878-15/536467213_802029125817849_2778243128245483357_n.jpg?stp=dst-jpg_e35_tt6&_nc_cat=109&ccb=1-7&_nc_sid=18de74&efg=eyJlZmdfdGFnIjoiQ0xJUFMuYmVzdF9pbWFnZV91cmxnZW4uQzMifQ%3D%3D&_nc_ohc=k36SjMy7v4oQ7kNvwGm299S&_nc_oc=AdmpJ3OYTRsBlBVUijU7nVuO6QOBqhbig9SgrZl3wQ9yKLYh8Wl7Y4tHKhG5G7sfxr0&_nc_zt=23&_nc_ht=scontent-ord5-3.cdninstagram.com&edm=AL-3X8kEAAAA&_nc_gid=abiAmay4kHKk2CacW0aRhA&oh=00_AfcXM4WD3b_HX4M7Its0zXhAVRR0rL_mzwP1Lhe0WQ47bQ&oe=68FE5C03 | G28: https://www.instagram.com/reel/DNiEQ7Bybpg/ | H28: 2025-08-19T10:00:09+0000 | I28: 52 | J28: 0 | K28: =LEN(B28) -> 617 | L28: =(DATEVALUE(LEFT(H28,10))+TIMEVALUE(MID(H28,12,8)))+(7/24) -> 45888.708 | M28: =TEXT(L28,"mmmm") -> August | N28: =VALUE(MID(H28,12,2)) -> 10 | O28: =LEN(B28)-LEN(SUBSTITUTE(B28,"#","")) -> 7
A29: 18078271180760880 | B29: Dirgahayu Republik Indonesia ke-80 🇮🇩 Mari terus menjaga semangat persatuan dan kemerdekaan demi Indonesia maju dan jaya.🤩🚀 #DirgahayuIndonesia #HUTRI80 #IndonesiaMerdeka #HariKemerdekaan #17Agustus #RepublikIndonesia #IndonesiaJaya | C29: IMAGE | D29: FEED | E29: https://scontent-ord5-2.cdninstagram.com/v/t51.82787-15/532992195_18474751429079669_6482308418317576689_n.jpg?stp=dst-jpg_e35_tt6&_nc_cat=102&ccb=1-7&_nc_sid=18de74&efg=eyJlZmdfdGFnIjoiRkVFRC5iZXN0X2ltYWdlX3VybGdlbi5DMyJ9&_nc_ohc=nhrsFEUWW3UQ7kNvwEzCgDi&_nc_oc=Adl2le0_bzfsmts_w3kHpPYlhCfwmC06KmOrhaGPZmuAG-iyLFztbfIV5RY_-5vHyI4&_nc_zt=23&_nc_ht=scontent-ord5-2.cdninstagram.com&edm=AL-3X8kEAAAA&_nc_gid=abiAmay4kHKk2CacW0aRhA&oh=00_AfeDCgDJaNAecbVJy1U32zem41tLzrIx42uFFJtHcVqHGg&oe=68FE64D6 | G29: https://www.instagram.com/p/DNcQBs7SDrn/ | H29: 2025-08-17T03:41:36+0000 | I29: 48 | J29: 1 | K29: =LEN(B29) -> 238 | L29: =(DATEVALUE(LEFT(H29,10))+TIMEVALUE(MID(H29,12,8)))+(7/24) -> 45886.446 | M29: =TEXT(L29,"mmmm") -> August | N29: =VALUE(MID(H29,12,2)) -> 3 | O29: =LEN(B29)-LEN(SUBSTITUTE(B29,"#","")) -> 7
